Workbook

Sheet Hypothèses
B2: TamCar — Budget 24 mois · HYPOTHÈSES
B3: Édition 2026-07 · Modifie UNIQUEMENT les cellules bleues, tout le reste se recalcule.
B5: A · Productivité d'un véhicule (scénario réaliste)
B6: Prix moyen d'une course | C6: 1500 | D6: Décision 2026-07 (au lieu de 2 500)
B7: Courses / jour / véhicule | C7: 10 | D7: Voiture & tricycle (moto = plus)
B8: Jours actifs / mois | C8: 26 | D8: Semaine de 6 jours (dimanche off)
B9: Volume de courses / véh / mois | C9: =C6*C7*C8 -> 390000 | D9: Calculé = prix × courses × jours
B11: B · Répartition de chaque course (split 40/10/30/20)
B12: Part plateforme (directe) | C12: 0.2 | D12: Revenu TamCar par course
B13: Part fonds rachat | C13: 0.1 | D13: Alimente le rachat véhicule
B14: Part plateforme du fonds rachat — An 1 | C14: 0.3 | D14: Dégressif
B15: Part plateforme du fonds rachat — An 2 | C15: 0.2 | D15: Dégressif
B16: Assurance conducteur / véh / mois | C16: 500 | D16: Prélèvement mensuel (revenu TamCar)
B17: Revenu plateforme / véh / mois — An 1 | C17: =C9*C12 + C9*C13*C14 + C16 -> 90200 | D17: 20% volume + 30% du rachat + assurance
B18: Revenu plateforme / véh / mois — An 2 | C18: =C9*C12 + C9*C13*C15 + C16 -> 86300 | D18: 20% volume + 20% du rachat + assurance
B20: C · Fiscalité & capital
B21: Impôt sur les sociétés (IS) | C21: 0.3 | D21: Sur résultat annuel positif
B22: Retenue IRCM sur dividendes | C22: 0.1 | D22: Prélevée à la distribution
B23: Taux de distribution des dividendes | C23: 0.4 | D23: % du résultat net distribué
B24: Trésorerie de départ | C24: 11000000 | D24: Levée 10 M + reliquat CAPEX
B25: Capital social total | C25: 30000000 | D25: 20 M apport IP + 10 M numéraire
B26: Ticket investisseur (référence) | C26: 1000000 | D26: Pour le calcul de rendement
B27: Multiple de valorisation à la sortie (An 5) | C27: 5 | D27: Valeur société = multiple × résultat net An 2
B29: Note : la trajectoire mensuelle des véhicules actifs est saisie dans l'onglet « Recettes » (ligne bleue).

Sheet Recettes
B2: Recettes plateforme — 24 mois
B4: Ligne | C4: M1 | D4: M2 | E4: M3 | F4: M4 | G4: M5 | H4: M6 | I4: M7 | J4: M8 | K4: M9 | L4: M10 | M4: M11 | N4: M12 | O4: M13 | P4: M14 | Q4: M15 | R4: M16 | S4: M17 | T4: M18 | U4: M19 | V4: M20 | W4: M21 | X4: M22 | Y4: M23 | Z4: M24
B5: Véhicules actifs | C5: 0 | D5: 0 | E5: 3 | F5: 5 | G5: 7 | H5: 10 | I5: 12 | J5: 13 | K5: 15 | L5: 17 | M5: 20 | N5: 25 | O5: 25 | P5: 26 | Q5: 27 | R5: 28 | S5: 29 | T5: 30 | U5: 30 | V5: 30 | W5: 30 | X5: 30 | Y5: 30 | Z5: 30
B6: Revenu / véh / mois | C6: =Hypothèses!$C$17 -> 90200 | D6: =Hypothèses!$C$17 -> 90200 | E6: =Hypothèses!$C$17 -> 90200 | F6: =Hypothèses!$C$17 -> 90200 | G6: =Hypothèses!$C$17 -> 90200 | H6: =Hypothèses!$C$17 -> 90200 | I6: =Hypothèses!$C$17 -> 90200 | J6: =Hypothèses!$C$17 -> 90200 | ... N6: =Hypothèses!$C$17 -> 90200 | O6: =Hypothèses!$C$18 -> 86300 | P6: =Hypothèses!$C$18 -> 86300 | Q6: =Hypothèses!$C$18 -> 86300 | R6: =Hypothèses!$C$18 -> 86300 | S6: =Hypothèses!$C$18 -> 86300 | T6: =Hypothèses!$C$18 -> 86300 | U6: =Hypothèses!$C$18 -> 86300 | V6: =Hypothèses!$C$18 -> 86300 | ... Z6: =Hypothèses!$C$18 -> 86300
B7: RECETTES PLATEFORME | C7: =C5*C6 -> 0 | D7: =D5*D6 -> 0 | E7: =E5*E6 -> 270600 | F7: =F5*F6 -> 451000 | G7: =G5*G6 -> 631400 | H7: =H5*H6 -> 902000 | I7: =I5*I6 -> 1082400 | J7: =J5*J6 -> 1172600 | ... Z7: =Z5*Z6 -> 2589000
B9: Total An 1 (M1-M12) | C9: =SUM(C7:N7) -> 11455400
B10: Total An 2 (M13-M24) | C10: =SUM(O7:Z7) -> 29773500
B11: Total 24 mois | C11: =C9+C10 -> 41228900

Sheet Charges
B2: Charges — CAPEX (démarrage) + OPEX mensuel
B4: CAPEX de démarrage (one-shot, imputé M1)
B5: Formalisation société (statuts + RCCM + IFU + annonce légale + valorisation App) | C5: 1500000
B6: ANATT — 1re autorisation + attestations + acomptes | C6: 666000
B7: Honoraires juriste OHADA (contrats) | C7: 300000
B8: Bureau — caution + aménagement | C8: 700000
B9: Matériel informatique + mobilier | C9: 1500000
B10: Marketing lancement (événement, photo, vidéo) | C10: 1500000
B11: Habillage 10 véhicules + inspections + kits | C11: 460000
B12: Charte visuelle + print + domaine/email | C12: 350000
B13: TOTAL CAPEX | C13: =SUM(C5:C12) -> 6976000
B15: OPEX mensuel par catégorie
B16: Catégorie | C16: M1 | D16: M2 | E16: M3 | F16: M4 | G16: M5 | H16: M6 | I16: M7 | J16: M8 | K16: M9 | L16: M10 | M16: M11 | N16: M12 | O16: M13 | P16: M14 | Q16: M15 | R16: M16 | S16: M17 | T16: M18 | U16: M19 | V16: M20 | W16: M21 | X16: M22 | Y16: M23 | Z16: M24
B17: Bureau & infrastructure
B18: Loyer | C18: 100000 | D18: 100000 | E18: 100000 | F18: 100000 | G18: 100000 | H18: 100000 | I18: 100000 | J18: 100000 | K18: 100000 | L18: 100000 | M18: 100000 | N18: 100000 | O18: 100000 | P18: 100000 | Q18: 100000 | R18: 100000 | S18: 100000 | T18: 100000 | U18: 100000 | V18: 100000 | W18: 100000 | X18: 100000 | Y18: 100000 | Z18: 100000
B19: Electricité et eau | C19: 100000 | D19: 100000 | E19: 100000 | F19: 100000 | G19: 100000 | H19: 100000 | I19: 100000 | J19: 100000 | K19: 100000 | L19: 100000 | M19: 100000 | N19: 100000 | O19: 100000 | P19: 100000 | Q19: 100000 | R19: 100000 | S19: 100000 | T19: 100000 | U19: 100000 | V19: 100000 | W19: 100000 | X19: 100000 | Y19: 100000 | Z19: 100000
B20: Déploiement technique
B21: Supabase Pro | C21: 15000 | D21: 15000 | E21: 15000 | F21: 15000 | G21: 15000 | H21: 15000 | I21: 15000 | J21: 15000 | K21: 15000 | L21: 15000 | M21: 15000 | N21: 15000 | O21: 15000 | P21: 15000 | Q21: 15000 | R21: 15000 | S21: 15000 | T21: 15000 | U21: 15000 | V21: 15000 | W21: 15000 | X21: 15000 | Y21: 15000 | Z21: 15000
B22: Vercel Pro | C22: 15000 | D22: 15000 | E22: 15000 | F22: 15000 | G22: 15000 | H22: 15000 | I22: 15000 | J22: 15000 | K22: 15000 | L22: 15000 | M22: 15000 | N22: 15000 | O22: 15000 | P22: 15000 | Q22: 15000 | R22: 15000 | S22: 15000 | T22: 15000 | U22: 15000 | V22: 15000 | W22: 15000 | X22: 15000 | Y22: 15000 | Z22: 15000
B23: Mapbox | C23: 25000 | D23: 25000 | E23: 25000 | F23: 25000 | G23: 25000 | H23: 25000 | I23: 25000 | J23: 25000 | K23: 25000 | L23: 25000 | M23: 25000 | N23: 25000 | O23: 25000 | P23: 25000 | Q23: 25000 | R23: 25000 | S23: 25000 | T23: 25000 | U23: 25000 | V23: 25000 | W23: 25000 | X23: 25000 | Y23: 25000 | Z23: 25000
B24: Twilio SMS | C24: 25000 | D24: 25000 | E24: 25000 | F24: 25000 | G24: 25000 | H24: 25000 | I24: 25000 | J24: 25000 | K24: 25000 | L24: 25000 | M24: 25000 | N24: 25000 | O24: 25000 | P24: 25000 | Q24: 25000 | R24: 25000 | S24: 25000 | T24: 25000 | U24: 25000 | V24: 25000 | W24: 25000 | X24: 25000 | Y24: 25000 | Z24: 25000
B25: IA Vision | C25: 10000 | D25: 10000 | E25: 10000 | F25: 10000 | G25: 10000 | H25: 10000 | I25: 10000 | J25: 10000 | K25: 10000 | L25: 10000 | M25: 10000 | N25: 10000 | O25: 10000 | P25: 10000 | Q25: 10000 | R25: 10000 | S25: 10000 | T25: 10000 | U25: 10000 | V25: 10000 | W25: 10000 | X25: 10000 | Y25: 10000 | Z25: 10000
B26: Claude Code | C26: 65000 | D26: 65000 | E26: 65000 | F26: 65000 | G26: 65000 | H26: 65000 | I26: 65000 | J26: 65000 | K26: 65000 | L26: 65000 | M26: 65000 | N26: 65000 | O26: 65000 | P26: 65000 | Q26: 65000 | R26: 65000 | S26: 65000 | T26: 65000 | U26: 65000 | V26: 65000 | W26: 65000 | X26: 65000 | Y26: 65000 | Z26: 65000
B27: Domaine pro + email pro | C27: 2500 | D27: 2500 | E27: 2500 | F27: 2500 | G27: 2500 | H27: 2500 | I27: 2500 | J27: 2500 | K27: 2500 | L27: 2500 | M27: 2500 | N27: 2500 | O27: 2500 | P27: 2500 | Q27: 2500 | R27: 2500 | S27: 2500 | T27: 2500 | U27: 2500 | V27: 2500 | W27: 2500 | X27: 2500 | Y27: 2500 | Z27: 2500
B28: Personnel de travail
B29: Secrétaire | C29: 100000 | D29: 100000 | E29: 100000 | F29: 100000 | G29: 100000 | H29: 100000 | I29: 100000 | J29: 100000 | K29: 100000 | L29: 100000 | M29: 100000 | N29: 100000 | O29: 100000 | P29: 100000 | Q29: 100000 | R29: 100000 | S29: 100000 | T29: 100000 | U29: 100000 | V29: 100000 | W29: 100000 | X29: 100000 | Y29: 100000 | Z29: 100000
B30: Community manager | C30: 75000 | D30: 75000 | E30: 75000 | F30: 75000 | G30: 75000 | H30: 75000 | I30: 75000 | J30: 75000 | K30: 75000 | L30: 75000 | M30: 75000 | N30: 75000 | O30: 75000 | P30: 75000 | Q30: 75000 | R30: 75000 | S30: 75000 | T30: 75000 | U30: 75000 | V30: 75000 | W30: 75000 | X30: 75000 | Y30: 75000 | Z30: 75000
B31: Comptable externe | C31: 75000 | D31: 75000 | E31: 75000 | F31: 75000 | G31: 75000 | H31: 75000 | I31: 75000 | J31: 75000 | K31: 75000 | L31: 75000 | M31: 75000 | N31: 75000 | O31: 75000 | P31: 75000 | Q31: 75000 | R31: 75000 | S31: 75000 | T31: 75000 | U31: 75000 | V31: 75000 | W31: 75000 | X31: 75000 | Y31: 75000 | Z31: 75000
B32: Juriste consultant | C32: 50000 | D32: 50000 | E32: 50000 | F32: 50000 | G32: 50000 | H32: 50000 | I32: 50000 | J32: 50000 | K32: 50000 | L32: 50000 | M32: 50000 | N32: 50000 | O32: 50000 | P32: 50000 | Q32: 50000 | R32: 50000 | S32: 50000 | T32: 50000 | U32: 50000 | V32: 50000 | W32: 50000 | X32: 50000 | Y32: 50000 | Z32: 50000
B33: Responsable opérations | H33: 200000 | I33: 200000 | J33: 200000 | K33: 200000 | L33: 200000 | M33: 200000 | N33: 200000 | O33: 200000 | P33: 200000 | Q33: 200000 | R33: 200000 | S33: 200000 | T33: 200000 | U33: 200000 | V33: 200000 | W33: 200000 | X33: 200000 | Y33: 200000 | Z33: 200000
B34: Actions communication et commerciales
B35: Ads Réseaux sociaux (Facebook + TikTok) | C35: 100000 | D35: 100000 | E35: 100000 | F35: 100000 | G35: 100000 | H35: 100000 | I35: 100000 | J35: 100000 | K35: 100000 | L35: 100000 | M35: 100000 | N35: 100000 | O35: 100000 | P35: 100000 | Q35: 100000 | R35: 100000 | S35: 100000 | T35: 100000 | U35: 100000 | V35: 100000 | W35: 100000 | X35: 100000 | Y35: 100000 | Z35: 100000
B36: Ads Google | C36: 30000 | D36: 30000 | E36: 30000 | F36: 30000 | G36: 30000 | H36: 30000 | I36: 30000 | J36: 30000 | K36: 30000 | L36: 30000 | M36: 30000 | N36: 30000 | O36: 30000 | P36: 30000 | Q36: 30000 | R36: 30000 | S36: 30000 | T36: 30000 | U36: 30000 | V36: 30000 | W36: 30000 | X36: 30000 | Y36: 30000 | Z36: 30000
B37: Radio locale (spots) | C37: 200000 | D37: 200000 | E37: 200000 | F37: 200000 | G37: 200000 | H37: 200000 | I37: 200000 | J37: 200000 | K37: 200000 | L37: 200000 | M37: 200000 | N37: 200000 | O37: 200000 | P37: 200000 | Q37: 200000 | R37: 200000 | S37: 200000 | T37: 200000 | U37: 200000 | V37: 200000 | W37: 200000 | X37: 200000 | Y37: 200000 | Z37: 200000
B38: Street marketing + flyers | C38: 1000000 | D38: 1000000 | E38: 1000000 | F38: 1000000 | G38: 1000000 | H38: 1000000 | I38: 500000 | J38: 500000 | K38: 500000 | L38: 500000 | M38: 500000 | N38: 500000 | O38: 500000 | P38: 500000 | Q38: 500000 | R38: 500000 | S38: 500000 | T38: 500000 | U38: 500000 | V38: 500000 | W38: 500000 | X38: 500000 | Y38: 500000 | Z38: 500000
B39: Parrainage (bonus 500 F) | C39: 100000 | D39: 100000 | E39: 100000 | F39: 100000 | G39: 100000 | H39: 100000 | I39: 100000 | J39: 100000 | K39: 100000 | L39: 100000 | M39: 100000 | N39: 100000 | O39: 100000 | P39: 100000 | Q39: 100000 | R39: 100000 | S39: 100000 | T39: 100000 | U39: 100000 | V39: 100000 | W39: 100000 | X39: 100000 | Y39: 100000 | Z39: 100000
B40: Frais financiers
B41: Financier & Mobile Money + assurance RC | C41: 77000 | D41: 77000 | E41: 77000 | F41: 77000 | G41: 77000 | H41: 77000 | I41: 77000 | J41: 77000 | K41: 77000 | L41: 77000 | M41: 77000 | N41: 77000 | O41: 82000 | P41: 82000 | Q41: 82000 | R41: 82000 | S41: 82000 | T41: 82000 | U41: 82000 | V41: 82000 | W41: 82000 | X41: 82000 | Y41: 82000 | Z41: 82000
B42: Ops manager (dès M18) | C42: 0 | D42: 0 | E42: 0 | F42: 0 | G42: 0 | H42: 0 | I42: 0 | J42: 0 | K42: 0 | L42: 0 | M42: 0 | N42: 0 | O42: 0 | P42: 0 | Q42: 0 | R42: 0 | S42: 0 | T42: 200000 | U42: 200000 | V42: 200000 | W42: 200000 | X42: 200000 | Y42: 200000 | Z42: 200000
B43: Extension Parakou (dès M18) | C43: 0 | D43: 0 | E43: 0 | F43: 0 | G43: 0 | H43: 0 | I43: 0 | J43: 0 | K43: 0 | L43: 0 | M43: 0 | N43: 0 | O43: 0 | P43: 0 | Q43: 0 | R43: 0 | S43: 0 | T43: 125000 | U43: 125000 | V43: 125000 | W43: 125000 | X43: 125000 | Y43: 125000 | Z43: 125000
...

Sheet P&L 24 mois
B2: P&L consolidé — 24 mois
B4: Poste | C4: M1 | D4: M2 | E4: M3 | F4: M4 | G4: M5 | H4: M6 | I4: M7 | J4: M8 | K4: M9 | L4: M10 | M4: M11 | N4: M12 | O4: M13 | P4: M14 | Q4: M15 | R4: M16 | S4: M17 | T4: M18 | U4: M19 | V4: M20 | W4: M21 | X4: M22 | Y4: M23 | Z4: M24
B5: Recettes plateforme | C5: =Recettes!C7 -> 0 | D5: =Recettes!D7 -> 0 | E5: =Recettes!E7 -> 270600 | F5: =Recettes!F7 -> 451000 | G5: =Recettes!G7 -> 631400 | H5: =Recettes!H7 -> 902000 | I5: =Recettes!I7 -> 1082400 | J5: =Recettes!J7 -> 1172600 | ... Z5: =Recettes!Z7 -> 2589000
B6: CAPEX (M1) | C6: =-Charges!$C$13 -> -6976000 | D6: 0 | E6: 0 | F6: 0 | G6: 0 | H6: 0 | I6: 0 | J6: 0 | K6: 0 | L6: 0 | M6: 0 | N6: 0 | O6: 0 | P6: 0 | Q6: 0 | R6: 0 | S6: 0 | T6: 0 | U6: 0 | V6: 0 | W6: 0 | X6: 0 | Y6: 0 | Z6: 0
B7: OPEX récurrent | C7: =-Charges!C44 -> -2164500 | D7: =-Charges!D44 -> -2164500 | E7: =-Charges!E44 -> -2164500 | F7: =-Charges!F44 -> -2164500 | G7: =-Charges!G44 -> -2164500 | H7: =-Charges!H44 -> -2364500 | I7: =-Charges!I44 -> -1864500 | J7: =-Charges!J44 -> -1864500 | ... Z7: =-Charges!Z44 -> -2194500
B8: Résultat avant impôt | C8: =C5+C6+C7 -> -9140500 | D8: =D5+D6+D7 -> -2164500 | E8: =E5+E6+E7 -> -1893900 | F8: =F5+F6+F7 -> -1713500 | G8: =G5+G6+G7 -> -1533100 | H8: =H5+H6+H7 -> -1462500 | I8: =I5+I6+I7 -> -782100 | J8: =J5+J6+J7 -> -691900 | ... Z8: =Z5+Z6+Z7 -> 394500
B10: Trésorerie début de mois | C10: =Hypothèses!$C$24 -> 11000000 | D10: =C11 -> 1859500 | E10: =D11 -> -305000 | F10: =E11 -> -2198900 | G10: =F11 -> -3912400 | H10: =G11 -> -5445500 | I10: =H11 -> -6908000 | J10: =I11 -> -7690100 | K10: =J11 -> -8382000 | ... Z10: =Y11 -> -4224600
B11: Trésorerie fin de mois | C11: =C10+C8 -> 1859500 | D11: =D10+D8 -> -305000 | E11: =E10+E8 -> -2198900 | F11: =F10+F8 -> -3912400 | G11: =G10+G8 -> -5445500 | H11: =H10+H8 -> -6908000 | I11: =I10+I8 -> -7690100 | J11: =J10+J8 -> -8382000 | ... Z11: =Z10+Z8 -> -3830100
B13: Synthèse
B14: Recettes An 1 | C14: =SUM(C5:N5) -> 11455400
B15: Recettes An 2 | C15: =SUM(O5:Z5) -> 29773500
B16: Charges An 1 (CAPEX+OPEX) | C16: =-SUM(C6:N7) -> 31350000
B17: Charges An 2 | C17: =-SUM(O6:Z7) -> 24709000
B18: Résultat avant impôt An 1 | C18: =C14-C16 -> -19894600
B19: Résultat avant impôt An 2 | C19: =C15-C17 -> 5064500
B20: IS An 2 (30% si positif) | C20: =-Hypothèses!$C$21*MAX(0,C19) -> -1519350
B21: Résultat NET An 2 | C21: =C19+C20 -> 3545150
B23: Trésorerie fin M12 | C23: =N11 -> -8894600
B24: Trésorerie fin M24 | C24: =Z11 -> -3830100

Sheet Investisseur
B2: Rendement investisseur — ticket 1 M FCFA
B3: Basé sur le P&L ci-contre (prix course 1 500 F). Hypothèse conservatrice.
B5: Part de l'investisseur au capital | C5: =Hypothèses!$C$26/Hypothèses!$C$25 -> 0.033333333 | D5: 1 M / 30 M
B7: Résultat net An 2 (société) | C7: ='P&L 24 mois'!C21 -> 3545150 | D7: Après IS
B8: Dividendes distribués An 2 (40%) | C8: =Hypothèses!$C$23*MAX(0,'P&L 24 mois'!C21) -> 1418060 | D8: Si résultat positif
B9: Part de l'investisseur (brut) | C9: =C5*C8 -> 47268.667 | D9: Sa quote-part
B10: Dividende net d'IRCM (An 2) | C10: =C9*(1-Hypothèses!$C$22) -> 42541.8 | D10: Après retenue 10%
B12: Dividendes nets cumulés ~5 ans | C12: =C10*3.5 -> 148896.3 | D12: Hyp. An3-5 ≈ 3,5× l'An 2 (croissance)
B14: Valeur de la société à la sortie | C14: =Hypothèses!$C$27*MAX(0,'P&L 24 mois'!C21) -> 17725750 | D14: Multiple × résultat net An 2
B15: Valeur du ticket à la sortie | C15: =C5*C14 -> 590858.33 | D15: Quote-part de l'investisseur
B17: Ticket de départ | C17: =Hypothèses!$C$26 -> 1000000
B18: RETOUR TOTAL (dividendes + plus-value) | C18: =C12+C15 -> 739754.63 | D18: Sur ~5 ans
B19: RETOUR en % du ticket | C19: =(C12+C15)/C17-1 -> -0.26024537
B21: ⚠️ Chiffres pilotés par les Hypothèses. La valorisation à la sortie dépend fortement du multiple (C27) et du résultat An 2 — à challenger avec un CFO.
