Workbook

Sheet Résumé
B2: Tam Logistics SARL — Budget prévisionnel 24 mois
B3: Édition juillet 2026 · Grand Nokoué · Bénin
B5: Hypothèses structurantes
B6: Levée numéraire cible | C6: 10 000 000 FCFA | D6: Concessionnaires + investisseurs passifs
B7: Apport IP fondateur (nature) | C7: 20 000 000 FCFA | D7: Application TamCar déjà déployée
B8: Capital total constitution | C8: 30 000 000 FCFA | D8: Valeur nominale part : 10 000 FCFA
B9: Salaire fondateur An 1 | C9: 0 FCFA | D9: Auto-financement, rémunération par dividendes à partir An 2
B10: Bureau physique | C10: Cotonou dès M0 | D10: Loyer + charges + internet fibre
B11: Banque compte pro | C11: Atlantic Bank ou BIIC | D11: À ouvrir M1
B12: Assurance RC pro plateforme | C12: 500 000 FCFA/an | D12: Placeholder — à réajuster après devis
B13: Cible véhicules actifs M+12 | C13: 25 véhicules | D13: Montée progressive 3 → 25 sur An 1
B14: Cible véhicules actifs M+24 | C14: 30 véhicules | D14: Extension géo Parakou/Bohicon en fin An 2
B15: Split recettes plateforme | C15: 20 % du volume + 20-30 % fonds rachat | D15: Cf. mémoire — Option Y validée 2026-07-16
B17: Synthèse chiffrée 24 mois
C18: Année 1 | D18: Année 2 | E18: Cumulé 24 mois
B19: CAPEX de démarrage | C19: ='CAPEX M0-M2'!C24 | D19: 0 | E19: ='CAPEX M0-M2'!C24
B20: OPEX récurrent | C20: ='OPEX An 1'!O44 | D20: ='OPEX An 2'!O54 | E20: =C20+D20
B21: Total charges | C21: =C19+C20 | D21: =D19+D20 | E21: =C21+D21
B22: Recettes plateforme | C22: ='Recettes 24 mois'!C9 | D22: ='Recettes 24 mois'!C10 | E22: =C22+D22
B23: Résultat brut | C23: =C22-C21 | D23: =D22-D21 | E23: =C23+D23
B25: Note : les valeurs sont estimatives, à réajuster après devis fournisseurs et retours terrain. Les onglets suivants sont éditables — modifier une cellule met à jour les totaux.

Sheet CAPEX M0-M2
B2: CAPEX de démarrage (one-shot M0 à M2)
A4: # | B4: Poste | C4: Montant | D4: Notes
A5: 1 | B5: Notaire — constitution SARL Tam Logistics | C5: 350000 | D5: Rédaction et enregistrement statuts, honoraires Cotonou
A6: 2 | B6: RCCM — immatriculation Registre du Commerce | C6: 50000
A7: 3 | B7: IFU — identifiant fiscal unique | C7: 10000
A8: 4 | B8: ANATT — autorisation exploitation VTC | C8: 300000 | D8: Fourchette 200-400 k FCFA au Bénin
A9: 5 | B9: Annonce légale de constitution | C9: 30000 | D9: Publication journal habilité
A10: 6 | B10: Ouverture compte pro (frais dossier) | C10: 25000 | D10: Atlantic Bank ou BIIC
A11: 7 | B11: Honoraires juriste OHADA — contrats | C11: 800000 | D11: CGU/CGV + contrat cession + contrat concessionnaire + pacte d'associés
A12: 8 | B12: Commissaire aux apports | C12: 750000 | D12: Obligatoire (apport IP > 5 M FCFA)
A13: 9 | B13: Bureau — caution 3 mois de loyer +2 mois de prépayé + caution électricité eau | C13: 500000 | D13: 5 × 100 000 FCFA
A14: 10 | B14: Bureau — aménagement | C14: 200000 | D14: Peinture, décoration, câblage
A15: 11 | B15: Matériel informatique + mobilier | C15: 700000 | D15: Ordi, imprimante, bureaux, chaises
A16: 12 | B16: Marketing lancement — événement pilote | C16: 400000 | D16: Press day + cocktail concessionnaires
A17: 13 | B17: Photoshoot voitures + chauffeurs | C17: 200000 | D17: Photographe pro, mise en valeur flotte
A18: 14 | B18: Habillage véhicules (autocollants) × 10 | C18: 300000 | D18: 30 000 FCFA / véhicule
A19: 15 | B19: Vidéo promo lancement | C19: 300000 | D19: Spot 30-60 sec + versions réseaux
... A23: 19 | B23: Nom de domaine + email pro | C23: 25000 | D23: tamcar.app + Google Workspace 1 an
B24: TOTAL CAPEX | C24: =SUM(C5:C23)

Sheet OPEX An 1
B2: OPEX An 1 — charges de fonctionnement mensuelles
A4: # | B4: Poste | C4: M1 | D4: M2 | E4: M3 | F4: M4 | G4: M5 | H4: M6 | I4: M7 | J4: M8 | K4: M9 | L4: M10 | M4: M11 | N4: M12 | O4: Total An
B5: Bureau & infrastructure
A6: 1 | B6: Loyer bureau Cotonou | C6: 100000 | D6: 100000 | E6: 100000 | F6: 100000 | G6: 100000 | H6: 100000 | I6: 100000 | J6: 100000 | K6: 100000 | L6: 100000 | M6: 100000 | N6: 100000 | O6: =SUM(C6:N6)
A7: 2 | B7: Électricité + eau | C7: 50000 | D7: 50000 | E7: 50000 | F7: 50000 | G7: 50000 | H7: 50000 | I7: 50000 | J7: 50000 | K7: 50000 | L7: 50000 | M7: 50000 | N7: 50000 | O7: =SUM(C7:N7)
A8: 3 | B8: Internet fibre | C8: 25000 | D8: 20000 | E8: 20000 | F8: 20000 | G8: 20000 | H8: 20000 | I8: 20000 | J8: 20000 | K8: 20000 | L8: 20000 | M8: 20000 | N8: 20000 | O8: =SUM(C8:N8)
A9: 4 | B9: Fournitures (papeterie) + gardiennage | C9: 30000 | D9: 30000 | E9: 30000 | F9: 30000 | G9: 30000 | H9: 30000 | I9: 30000 | J9: 30000 | K9: 30000 | L9: 30000 | M9: 30000 | N9: 30000 | O9: =SUM(C9:N9)
B10: Sous-total Bureau & infrastructure | C10: =SUM(C6:C9) | D10: =SUM(D6:D9) | E10: =SUM(E6:E9) | F10: =SUM(F6:F9) | G10: =SUM(G6:G9) | H10: =SUM(H6:H9) | I10: =SUM(I6:I9) | J10: =SUM(J6:J9) | ... N10: =SUM(N6:N9) | O10: =SUM(C10:N10)
B12: Tech & infrastructure logicielle
A13: 1 | B13: Supabase Pro | C13: 15000 | D13: 15000 | E13: 15000 | F13: 15000 | G13: 15000 | H13: 15000 | I13: 15000 | J13: 15000 | K13: 15000 | L13: 15000 | M13: 15000 | N13: 15000 | O13: =SUM(C13:N13)
A14: 2 | B14: Vercel Pro | C14: 12000 | D14: 12000 | E14: 12000 | F14: 12000 | G14: 12000 | H14: 12000 | I14: 12000 | J14: 12000 | K14: 12000 | L14: 12000 | M14: 12000 | N14: 12000 | O14: =SUM(C14:N14)
A15: 3 | B15: Mapbox (géocodage + tuiles) | C15: 25000 | D15: 25000 | E15: 25000 | F15: 25000 | G15: 25000 | H15: 25000 | I15: 25000 | J15: 25000 | K15: 25000 | L15: 25000 | M15: 25000 | N15: 25000 | O15: =SUM(C15:N15)
A16: 4 | B16: Twilio SMS (OTP auth) | C16: 20000 | D16: 20000 | E16: 20000 | F16: 20000 | G16: 20000 | H16: 20000 | I16: 20000 | J16: 20000 | K16: 20000 | L16: 20000 | M16: 20000 | N16: 20000 | O16: =SUM(C16:N16)
A17: 5 | B17: Nom de domaine + email pro | C17: 2000 | D17: 2000 | E17: 2000 | F17: 2000 | G17: 2000 | H17: 2000 | I17: 2000 | J17: 2000 | K17: 2000 | L17: 2000 | M17: 2000 | N17: 2000 | O17: =SUM(C17:N17)
A18: 6 | B18: IA Vision (KYC + photos véhicules) | C18: 10000 | D18: 10000 | E18: 10000 | F18: 10000 | G18: 10000 | H18: 10000 | I18: 10000 | J18: 10000 | K18: 10000 | L18: 10000 | M18: 10000 | N18: 10000 | O18: =SUM(C18:N18)
A19: 7 | B19: Monitoring (Sentry, uptime) | C19: 0 | D19: 0 | E19: 0 | F19: 0 | G19: 0 | H19: 0 | I19: 0 | J19: 0 | K19: 0 | L19: 0 | M19: 0 | N19: 0 | O19: =SUM(C19:N19)
B20: Sous-total Tech & infrastructure logicielle | C20: =SUM(C13:C19) | D20: =SUM(D13:D19) | E20: =SUM(E13:E19) | F20: =SUM(F13:F19) | G20: =SUM(G13:G19) | H20: =SUM(H13:H19) | I20: =SUM(I13:I19) | J20: =SUM(J13:J19) | ... N20: =SUM(N13:N19) | O20: =SUM(C20:N20)
B22: RH externalisée
A23: 1 | B23: Support client (freelance) | C23: 100000 | D23: 100000 | E23: 100000 | F23: 100000 | G23: 100000 | H23: 100000 | I23: 100000 | J23: 100000 | K23: 100000 | L23: 100000 | M23: 100000 | N23: 100000 | O23: =SUM(C23:N23)
A24: 2 | B24: Community manager (forfait) | C24: 75000 | D24: 75000 | E24: 75000 | F24: 75000 | G24: 75000 | H24: 75000 | I24: 75000 | J24: 75000 | K24: 75000 | L24: 75000 | M24: 75000 | N24: 75000 | O24: =SUM(C24:N24)
A25: 3 | B25: Comptable externe (forfait) | C25: 50000 | D25: 50000 | E25: 50000 | F25: 50000 | G25: 50000 | H25: 50000 | I25: 50000 | J25: 50000 | K25: 50000 | L25: 50000 | M25: 50000 | N25: 50000 | O25: =SUM(C25:N25)
A26: 4 | B26: Juriste rétainer | C26: 50000 | D26: 50000 | E26: 50000 | F26: 50000 | G26: 50000 | H26: 50000 | I26: 50000 | J26: 50000 | K26: 50000 | L26: 50000 | M26: 50000 | N26: 50000 | O26: =SUM(C26:N26)
B27: Sous-total RH externalisée | C27: =SUM(C23:C26) | D27: =SUM(D23:D26) | E27: =SUM(E23:E26) | F27: =SUM(F23:F26) | G27: =SUM(G23:G26) | H27: =SUM(H23:H26) | I27: =SUM(I23:I26) | J27: =SUM(J23:J26) | ... N27: =SUM(N23:N26) | O27: =SUM(C27:N27)
B29: Marketing & acquisition
A30: 1 | B30: Ads Meta (Facebook + Instagram) | C30: 100000 | D30: 100000 | E30: 100000 | F30: 100000 | G30: 100000 | H30: 100000 | I30: 100000 | J30: 100000 | K30: 100000 | L30: 100000 | M30: 100000 | N30: 100000 | O30: =SUM(C30:N30)
A31: 2 | B31: Ads Google | C31: 75000 | D31: 75000 | E31: 75000 | F31: 75000 | G31: 75000 | H31: 75000 | I31: 75000 | J31: 75000 | K31: 75000 | L31: 75000 | M31: 75000 | N31: 75000 | O31: =SUM(C31:N31)
A32: 3 | B32: Influenceurs locaux | C32: 75000 | D32: 75000 | E32: 75000 | F32: 75000 | G32: 75000 | H32: 75000 | I32: 75000 | J32: 75000 | K32: 75000 | L32: 75000 | M32: 75000 | N32: 75000 | O32: =SUM(C32:N32)
A33: 4 | B33: Radio locale (spots) | C33: 100000 | D33: 100000 | E33: 100000 | F33: 100000 | G33: 100000 | H33: 100000 | I33: 100000 | J33: 100000 | K33: 100000 | L33: 100000 | M33: 100000 | N33: 100000 | O33: =SUM(C33:N33)
A34: 5 | B34: Street marketing + flyers | C34: 50000 | D34: 50000 | E34: 50000 | F34: 50000 | G34: 50000 | H34: 50000 | I34: 50000 | J34: 50000 | K34: 50000 | L34: 50000 | M34: 50000 | N34: 50000 | O34: =SUM(C34:N34)
A35: 6 | B35: Parrainage bonus 500 FCFA | C35: 50000 | D35: 50000 | E35: 50000 | F35: 50000 | G35: 50000 | H35: 50000 | I35: 50000 | J35: 50000 | K35: 50000 | L35: 50000 | M35: 50000 | N35: 50000 | O35: =SUM(C35:N35)
B36: Sous-total Marketing & acquisition | C36: =SUM(C30:C35) | D36: =SUM(D30:D35) | E36: =SUM(E30:E35) | F36: =SUM(F30:F35) | G36: =SUM(G30:G35) | H36: =SUM(H30:H35) | I36: =SUM(I30:I35) | J36: =SUM(J30:J35) | ... N36: =SUM(N30:N35) | O36: =SUM(C36:N36)
B38: Financier & assurance
A39: 1 | B39: Frais tenue compte pro | C39: 5500 | D39: 5500 | E39: 5500 | F39: 5500 | G39: 5500 | H39: 5500 | I39: 5500 | J39: 5500 | K39: 5500 | L39: 5500 | M39: 5500 | N39: 5500 | O39: =SUM(C39:N39)
A40: 2 | B40: Frais Mobile Money out (retraits) | C40: 30000 | D40: 30000 | E40: 30000 | F40: 30000 | G40: 30000 | H40: 30000 | I40: 30000 | J40: 30000 | K40: 30000 | L40: 30000 | M40: 30000 | N40: 30000 | O40: =SUM(C40:N40)
A41: 3 | B41: Assurance RC pro plateforme | C41: 41666 | D41: 41666 | E41: 41666 | F41: 41666 | G41: 41666 | H41: 41666 | I41: 41666 | J41: 41666 | K41: 41666 | L41: 41666 | M41: 41666 | N41: 41666 | O41: =SUM(C41:N41)
B42: Sous-total Financier & assurance | C42: =SUM(C39:C41) | D42: =SUM(D39:D41) | E42: =SUM(E39:E41) | F42: =SUM(F39:F41) | G42: =SUM(G39:G41) | H42: =SUM(H39:H41) | I42: =SUM(I39:I41) | J42: =SUM(J39:J41) | ... N42: =SUM(N39:N41) | O42: =SUM(C42:N42)
B44: TOTAL OPEX MENSUEL | C44: =C10+C20+C27+C36+C42 | D44: =D10+D20+D27+D36+D42 | E44: =E10+E20+E27+E36+E42 | F44: =F10+F20+F27+F36+F42 | G44: =G10+G20+G27+G36+G42 | H44: =H10+H20+H27+H36+H42 | I44: =I10+I20+I27+I36+I42 | J44: =J10+J20+J27+J36+J42 | ... N44: =N10+N20+N27+N36+N42 | O44: =SUM(C44:N44)

Sheet OPEX An 2
B2: OPEX An 2 — charges de fonctionnement mensuelles
A4: # | B4: Poste | C4: M13 | D4: M14 | E4: M15 | F4: M16 | G4: M17 | H4: M18 | I4: M19 | J4: M20 | K4: M21 | L4: M22 | M4: M23 | N4: M24 | O4: Total An
B5: Bureau & infrastructure
A6: 1 | B6: Loyer bureau Cotonou | C6: 100000 | D6: 100000 | E6: 100000 | F6: 100000 | G6: 100000 | H6: 100000 | I6: 100000 | J6: 100000 | K6: 100000 | L6: 100000 | M6: 100000 | N6: 100000 | O6: =SUM(C6:N6)
A7: 2 | B7: Électricité + eau | C7: 50000 | D7: 50000 | E7: 50000 | F7: 50000 | G7: 50000 | H7: 50000 | I7: 50000 | J7: 50000 | K7: 50000 | L7: 50000 | M7: 50000 | N7: 50000 | O7: =SUM(C7:N7)
A8: 3 | B8: Internet fibre | C8: 20000 | D8: 20000 | E8: 20000 | F8: 20000 | G8: 20000 | H8: 20000 | I8: 20000 | J8: 20000 | K8: 20000 | L8: 20000 | M8: 20000 | N8: 20000 | O8: =SUM(C8:N8)
A9: 4 | B9: Fournitures + gardiennage | C9: 30000 | D9: 30000 | E9: 30000 | F9: 30000 | G9: 30000 | H9: 30000 | I9: 30000 | J9: 30000 | K9: 30000 | L9: 30000 | M9: 30000 | N9: 30000 | O9: =SUM(C9:N9)
B10: Sous-total Bureau & infrastructure | C10: =SUM(C6:C9) | D10: =SUM(D6:D9) | E10: =SUM(E6:E9) | F10: =SUM(F6:F9) | G10: =SUM(G6:G9) | H10: =SUM(H6:H9) | I10: =SUM(I6:I9) | J10: =SUM(J6:J9) | ... N10: =SUM(N6:N9) | O10: =SUM(C10:N10)
B12: Tech & infrastructure logicielle
A13: 1 | B13: Supabase Pro | C13: 15000 | D13: 15000 | E13: 15000 | F13: 15000 | G13: 15000 | H13: 15000 | I13: 15000 | J13: 15000 | K13: 15000 | L13: 15000 | M13: 15000 | N13: 15000 | O13: =SUM(C13:N13)
A14: 2 | B14: Vercel Pro | C14: 12000 | D14: 12000 | E14: 12000 | F14: 12000 | G14: 12000 | H14: 12000 | I14: 12000 | J14: 12000 | K14: 12000 | L14: 12000 | M14: 12000 | N14: 12000 | O14: =SUM(C14:N14)
A15: 3 | B15: Mapbox (géocodage + tuiles) | C15: 25000 | D15: 25000 | E15: 25000 | F15: 25000 | G15: 25000 | H15: 25000 | I15: 25000 | J15: 25000 | K15: 25000 | L15: 25000 | M15: 25000 | N15: 25000 | O15: =SUM(C15:N15)
A16: 4 | B16: Twilio SMS (OTP auth) | C16: 20000 | D16: 20000 | E16: 20000 | F16: 20000 | G16: 20000 | H16: 20000 | I16: 20000 | J16: 20000 | K16: 20000 | L16: 20000 | M16: 20000 | N16: 20000 | O16: =SUM(C16:N16)
A17: 5 | B17: Nom de domaine + email pro | C17: 1500 | D17: 1500 | E17: 1500 | F17: 1500 | G17: 1500 | H17: 1500 | I17: 1500 | J17: 1500 | K17: 1500 | L17: 1500 | M17: 1500 | N17: 1500 | O17: =SUM(C17:N17)
A18: 6 | B18: IA Vision (KYC + photos véhicules) | C18: 10000 | D18: 10000 | E18: 10000 | F18: 10000 | G18: 10000 | H18: 10000 | I18: 10000 | J18: 10000 | K18: 10000 | L18: 10000 | M18: 10000 | N18: 10000 | O18: =SUM(C18:N18)
A19: 7 | B19: Monitoring (Sentry, uptime) | C19: 0 | D19: 0 | E19: 0 | F19: 0 | G19: 0 | H19: 0 | I19: 0 | J19: 0 | K19: 0 | L19: 0 | M19: 0 | N19: 0 | O19: =SUM(C19:N19)
B20: Sous-total Tech & infrastructure logicielle | C20: =SUM(C13:C19) | D20: =SUM(D13:D19) | E20: =SUM(E13:E19) | F20: =SUM(F13:F19) | G20: =SUM(G13:G19) | H20: =SUM(H13:H19) | I20: =SUM(I13:I19) | J20: =SUM(J13:J19) | ... N20: =SUM(N13:N19) | O20: =SUM(C20:N20)
B22: RH externalisée
A23: 1 | B23: Support client (freelance) | C23: 100000 | D23: 100000 | E23: 100000 | F23: 100000 | G23: 100000 | H23: 100000 | I23: 100000 | J23: 100000 | K23: 100000 | L23: 100000 | M23: 100000 | N23: 100000 | O23: =SUM(C23:N23)
A24: 2 | B24: Community manager (forfait) | C24: 75000 | D24: 75000 | E24: 75000 | F24: 75000 | G24: 75000 | H24: 75000 | I24: 75000 | J24: 75000 | K24: 75000 | L24: 75000 | M24: 75000 | N24: 75000 | O24: =SUM(C24:N24)
A25: 3 | B25: Comptable externe (forfait) | C25: 50000 | D25: 50000 | E25: 50000 | F25: 50000 | G25: 50000 | H25: 50000 | I25: 50000 | J25: 50000 | K25: 50000 | L25: 50000 | M25: 50000 | N25: 50000 | O25: =SUM(C25:N25)
A26: 4 | B26: Juriste rétainer | C26: 50000 | D26: 50000 | E26: 50000 | F26: 50000 | G26: 50000 | H26: 50000 | I26: 50000 | J26: 50000 | K26: 50000 | L26: 50000 | M26: 50000 | N26: 50000 | O26: =SUM(C26:N26)
A27: 5 | B27: Ops manager (freelance/CDD) | C27: 0 | D27: 0 | E27: 0 | F27: 0 | G27: 0 | H27: 200000 | I27: 200000 | J27: 200000 | K27: 200000 | L27: 200000 | M27: 200000 | N27: 200000 | O27: =SUM(C27:N27)
B28: Sous-total RH externalisée | C28: =SUM(C23:C27) | D28: =SUM(D23:D27) | E28: =SUM(E23:E27) | F28: =SUM(F23:F27) | G28: =SUM(G23:G27) | H28: =SUM(H23:H27) | I28: =SUM(I23:I27) | J28: =SUM(J23:J27) | ... N28: =SUM(N23:N27) | O28: =SUM(C28:N28)
B30: Marketing & acquisition
A31: 1 | B31: Ads Meta (Facebook + Instagram) | C31: 225000 | D31: 225000 | E31: 225000 | F31: 225000 | G31: 225000 | H31: 225000 | I31: 225000 | J31: 225000 | K31: 225000 | L31: 225000 | M31: 225000 | N31: 225000 | O31: =SUM(C31:N31)
A32: 2 | B32: Ads Google | C32: 112500 | D32: 112500 | E32: 112500 | F32: 112500 | G32: 112500 | H32: 112500 | I32: 112500 | J32: 112500 | K32: 112500 | L32: 112500 | M32: 112500 | N32: 112500 | O32: =SUM(C32:N32)
A33: 3 | B33: Influenceurs locaux | C33: 112500 | D33: 112500 | E33: 112500 | F33: 112500 | G33: 112500 | H33: 112500 | I33: 112500 | J33: 112500 | K33: 112500 | L33: 112500 | M33: 112500 | N33: 112500 | O33: =SUM(C33:N33)
A34: 4 | B34: Radio locale (spots) | C34: 150000 | D34: 150000 | E34: 150000 | F34: 150000 | G34: 150000 | H34: 150000 | I34: 150000 | J34: 150000 | K34: 150000 | L34: 150000 | M34: 150000 | N34: 150000 | O34: =SUM(C34:N34)
A35: 5 | B35: Street marketing + flyers | C35: 75000 | D35: 75000 | E35: 75000 | F35: 75000 | G35: 75000 | H35: 75000 | I35: 75000 | J35: 75000 | K35: 75000 | L35: 75000 | M35: 75000 | N35: 75000 | O35: =SUM(C35:N35)
A36: 6 | B36: Parrainage bonus 500 FCFA | C36: 75000 | D36: 75000 | E36: 75000 | F36: 75000 | G36: 75000 | H36: 75000 | I36: 75000 | J36: 75000 | K36: 75000 | L36: 75000 | M36: 75000 | N36: 75000 | O36: =SUM(C36:N36)
B37: Sous-total Marketing & acquisition | C37: =SUM(C31:C36) | D37: =SUM(D31:D36) | E37: =SUM(E31:E36) | F37: =SUM(F31:F36) | G37: =SUM(G31:G36) | H37: =SUM(H31:H36) | I37: =SUM(I31:I36) | J37: =SUM(J31:J36) | ... N37: =SUM(N31:N36) | O37: =SUM(C37:N37)
B39: Financier & assurance
A40: 1 | B40: Frais tenue compte pro | C40: 10000 | D40: 10000 | E40: 10000 | F40: 10000 | G40: 10000 | H40: 10000 | I40: 10000 | J40: 10000 | K40: 10000 | L40: 10000 | M40: 10000 | N40: 10000 | O40: =SUM(C40:N40)
A41: 2 | B41: Frais Mobile Money out (retraits) | C41: 30000 | D41: 30000 | E41: 30000 | F41: 30000 | G41: 30000 | H41: 30000 | I41: 30000 | J41: 30000 | K41: 30000 | L41: 30000 | M41: 30000 | N41: 30000 | O41: =SUM(C41:N41)
A42: 3 | B42: Assurance RC pro plateforme | C42: 41666 | D42: 41666 | E42: 41666 | F42: 41666 | G42: 41666 | H42: 41666 | I42: 41666 | J42: 41666 | K42: 41666 | L42: 41666 | M42: 41666 | N42: 41666 | O42: =SUM(C42:N42)
B43: Sous-total Financier & assurance | C43: =SUM(C40:C42) | D43: =SUM(D40:D42) | E43: =SUM(E40:E42) | F43: =SUM(F40:F42) | G43: =SUM(G40:G42) | H43: =SUM(H40:H42) | I43: =SUM(I40:I42) | J43: =SUM(J40:J42) | ... N43: =SUM(N40:N42) | O43: =SUM(C43:N43)
B45: Extension géographique
A46: 1 | B46: Loyer bureau annexe Parakou | C46: 0 | D46: 0 | E46: 0 | F46: 0 | G46: 0 | H46: 100000 | I46: 100000 | J46: 100000 | K46: 100000 | L46: 100000 | M46: 100000 | N46: 100000 | O46: =SUM(C46:N46)
A47: 2 | B47: Charges Parakou (élec + internet) | C47: 0 | D47: 0 | E47: 0 | F47: 0 | G47: 0 | H47: 25000 | I47: 25000 | J47: 25000 | K47: 25000 | L47: 25000 | M47: 25000 | N47: 25000 | O47: =SUM(C47:N47)
...

Sheet Recettes 24 mois
B2: Recettes plateforme TamCar — projection 24 mois
A4: # | B4: Ligne | C4: M1 | D4: M2 | E4: M3 | F4: M4 | G4: M5 | H4: M6 | I4: M7 | J4: M8 | K4: M9 | L4: M10 | M4: M11 | N4: M12 | O4: M13 | P4: M14 | Q4: M15 | R4: M16 | S4: M17 | T4: M18 | U4: M19 | V4: M20 | W4: M21 | X4: M22 | Y4: M23 | Z4: M24 | AA4: Total 24m
A5: 1 | B5: Nb véhicules actifs | C5: 0 | D5: 0 | E5: 3 | F5: 5 | G5: 7 | H5: 10 | I5: 12 | J5: 13 | K5: 15 | L5: 17 | M5: 20 | N5: 25 | O5: 25 | P5: 26 | Q5: 27 | R5: 28 | S5: 29 | T5: 30 | U5: 30 | V5: 30 | W5: 30 | X5: 30 | Y5: 30 | Z5: 30
A6: 2 | B6: Recette plateforme / véh / mois | C6: 70000 | D6: 70000 | E6: 70000 | F6: 70000 | G6: 70000 | H6: 70000 | I6: 70000 | J6: 70000 | K6: 70000 | L6: 70000 | M6: 70000 | N6: 70000 | O6: 100000 | P6: 120000 | Q6: 130000 | R6: 140000 | S6: 140000 | T6: 140000 | U6: 140000 | V6: 140000 | W6: 140000 | X6: 140000 | Y6: 140000 | Z6: 140000
A7: 3 | B7: RECETTES PLATEFORME TOTAL | C7: =C5*C6 | D7: =D5*D6 | E7: =E5*E6 | F7: =F5*F6 | G7: =G5*G6 | H7: =H5*H6 | I7: =I5*I6 | J7: =J5*J6 | ... Z7: =Z5*Z6 | AA7: =SUM(C7:Z7)
B9: Récap An 1 (M1-M12) | C9: =SUM(C7:N7)
B10: Récap An 2 (M13-M24) | C10: =SUM(O7:Z7)
B11: Total 24 mois | C11: =SUM(C7:Z7)
B14: Méthodologie
B15: Recette plateforme = 20 % du volume brut par course + part sur fonds rachat (30 % An 1 → 20 % An 2).
B16: An 1 (scénario prudent) : 10 courses/j × 25 j × 1 200 FCFA prix moyen = 300 000 FCFA volume/véh/mois.
B17: → Plateforme : 20 % × 300 000 + 30 % × 30 000 (rachat) = 69 000 → arrondi 70 000 FCFA/véh/mois.
B18: An 2 (scénario réaliste, maturité) : 10 courses/j × 26 j × 2 500 FCFA = 650 000 FCFA volume/véh/mois.
B19: → Plateforme : 20 % × 650 000 + 15 % × 65 000 (rachat, moyenne An 2) = 140 000 FCFA/véh/mois.
B20: Montée en charge véhicules : 0 → 25 sur An 1 (onboarding progressif), 25 → 30 sur An 2 (extension Parakou).
B21: Pour ajuster : modifier les valeurs des lignes 5 (véhicules) et 6 (recette unitaire), les totaux se recalculent automatiquement.

Sheet P&L 24 mois
B2: P&L consolidé — 24 mois
B4: Poste | C4: M1 | D4: M2 | E4: M3 | F4: M4 | G4: M5 | H4: M6 | I4: M7 | J4: M8 | K4: M9 | L4: M10 | M4: M11 | N4: M12 | O4: M13 | P4: M14 | Q4: M15 | R4: M16 | S4: M17 | T4: M18 | U4: M19 | V4: M20 | W4: M21 | X4: M22 | Y4: M23 | Z4: M24 | AA4: Total
B5: Recettes plateforme | C5: ='Recettes 24 mois'!C7 | D5: ='Recettes 24 mois'!D7 | E5: ='Recettes 24 mois'!E7 | F5: ='Recettes 24 mois'!F7 | G5: ='Recettes 24 mois'!G7 | H5: ='Recettes 24 mois'!H7 | I5: ='Recettes 24 mois'!I7 | J5: ='Recettes 24 mois'!J7 | ... Z5: ='Recettes 24 mois'!Z7 | AA5: =SUM(C5:Z5)
B6: CAPEX (M1 uniquement) | C6: ='CAPEX M0-M2'!C24 | D6: 0 | E6: 0 | F6: 0 | G6: 0 | H6: 0 | I6: 0 | J6: 0 | K6: 0 | L6: 0 | M6: 0 | N6: 0 | O6: 0 | P6: 0 | Q6: 0 | R6: 0 | S6: 0 | T6: 0 | U6: 0 | V6: 0 | W6: 0 | X6: 0 | Y6: 0 | Z6: 0 | AA6: =C6
B7: OPEX récurrent | C7: ='OPEX An 1'!C44 | D7: ='OPEX An 1'!D44 | E7: ='OPEX An 1'!E44 | F7: ='OPEX An 1'!F44 | G7: ='OPEX An 1'!G44 | H7: ='OPEX An 1'!H44 | I7: ='OPEX An 1'!I44 | J7: ='OPEX An 1'!J44 | ... N7: ='OPEX An 1'!N44 | O7: ='OPEX An 2'!C54 | P7: ='OPEX An 2'!D54 | Q7: ='OPEX An 2'!E54 | R7: ='OPEX An 2'!F54 | S7: ='OPEX An 2'!G54 | T7: ='OPEX An 2'!H54 | U7: ='OPEX An 2'!I54 | V7: ='OPEX An 2'!J54 | ... Z7: ='OPEX An 2'!N54 | AA7: =SUM(C7:Z7)
B8: Total charges mensuelles | C8: =C6+C7 | D8: =D6+D7 | E8: =E6+E7 | F8: =F6+F7 | G8: =G6+G7 | H8: =H6+H7 | I8: =I6+I7 | J8: =J6+J7 | ... Z8: =Z6+Z7 | AA8: =SUM(C8:Z8)
B9: Résultat mensuel | C9: =C5-C8 | D9: =D5-D8 | E9: =E5-E8 | F9: =F5-F8 | G9: =G5-G8 | H9: =H5-H8 | I9: =I5-I8 | J9: =J5-J8 | ... Z9: =Z5-Z8 | AA9: =SUM(C9:Z9)
B11: Trésorerie début de mois | C11: 11000000 | D11: =C12 | E11: =D12 | F11: =E12 | G11: =F12 | H11: =G12 | I11: =H12 | J11: =I12 | K11: =J12 | ... Z11: =Y12
B12: Trésorerie fin de mois | C12: =C11+C9 | D12: =D11+D9 | E12: =E11+E9 | F12: =F11+F9 | G12: =G11+G9 | H12: =H11+H9 | I12: =I11+I9 | J12: =J11+J9 | ... Z12: =Z11+Z9
B15: Lecture du P&L
B16: Ligne 5 : recettes plateforme (proviennent de l'onglet Recettes 24 mois).
B17: Ligne 6 : CAPEX one-shot imputé sur M1.
B18: Ligne 7 : OPEX récurrent (proviennent des onglets OPEX An 1 et An 2).
B19: Ligne 9 : résultat mensuel = recettes − (CAPEX + OPEX). Négatif jusqu'au point mort, positif ensuite.
B20: Ligne 11-12 : trésorerie cumulée. On démarre à 11 M FCFA (levée 10 M + ADR ~1 M des premiers concess).
B21: Point mort mensuel : quand ligne 9 devient positive (typiquement autour du M9-M10 selon montée en charge).
B22: Point mort cumulé : quand ligne 12 devient positive et se maintient (typiquement M14-M16).

Sheet Cash flow ADR
B2: Cash flow ADR — Avances de démarrage concessionnaires
B3: Mouvement de trésorerie bilanciel — neutre au résultat P&L
B5: Nature comptable
B6: L'ADR (Avance de Démarrage Remboursable) versée par un concessionnaire à la signature
B7: n'est ni un revenu ni un apport en capital. C'est une DETTE de la société envers ce
B8: concessionnaire, comptabilisée au PASSIF CIRCULANT : « Dettes envers partenaires »
B9: (Art. 1892 Code civil OHADA + convention libre entre parties).
B11: L'encaissement à la signature et le remboursement à M+12 après mise en service du 1er
B12: véhicule sont donc des MOUVEMENTS DE TRÉSORERIE — ils impactent le cash, pas le résultat.
B14: Section 1 — Encaissements (rentrées de trésorerie)
B15: Mois | C15: Nb concess signés | D15: ADR par concess | E15: Total encaissé
B16: M1 | C16: 3 | D16: 100000 | E16: =C16*D16
B17: M2 | C17: 2 | D17: 100000 | E17: =C17*D17
B18: M3 | C18: 2 | D18: 100000 | E18: =C18*D18
B19: M4 | C19: 1 | D19: 100000 | E19: =C19*D19
B20: M5 | C20: 1 | D20: 100000 | E20: =C20*D20
B21: M6 | C21: 1 | D21: 100000 | E21: =C21*D21
B22: TOTAL encaissements | C22: =SUM(C16:C21) | E22: =SUM(E16:E21)
B24: Section 2 — Décaissements (sorties de trésorerie, remboursements)
B25: Remboursement à M+12 après mise en service du 1er véhicule (mémoire section 3-bis)
B26: Mois | C26: Nb concess remboursés | D26: ADR par concess | E26: Total décaissé
B27: M15 | C27: 3 | D27: 100000 | E27: =-C27*D27
B28: M16 | C28: 2 | D28: 100000 | E28: =-C28*D28
B29: M17 | C29: 2 | D29: 100000 | E29: =-C29*D29
B30: M18 | C30: 1 | D30: 100000 | E30: =-C30*D30
B31: M19 | C31: 1 | D31: 100000 | E31: =-C31*D31
B32: M20 | C32: 1 | D32: 100000 | E32: =-C32*D32
B33: TOTAL décaissements | C33: =SUM(C27:C32) | E33: =SUM(E27:E32)
B35: Section 3 — Solde ADR sur 24 mois
B36: Encaissements cumulés | E36: =E22
B37: Décaissements cumulés | E37: =E33
B38: SOLDE (doit tendre vers 0) | E38: =E22+E33
B40: Section 4 — Financement (part plateforme du fonds rachat)
B41: Le remboursement des 1 M FCFA d'ADR est financé par la part plateforme du fonds rachat
B42: (30 % An 1 → 20 % An 2). Calcul avec la projection actuelle (25 véh An 1, 30 véh An 2) :
B44: An 1 : 25 véh (fin An 1) × 300 k FCFA volume/véh × 10 % rachat × 30 % plateforme = 22,5 k/véh/an
B45: → cumul An 1 ≈ 1,15 M FCFA (avec montée en charge progressive)
B46: An 2 : 30 véh × 650 k FCFA volume/véh × 10 % rachat × 20 % plateforme = 15,6 k/véh/an
B47: → cumul An 2 ≈ 4,17 M FCFA
B49: TOTAL part plateforme fonds rachat sur 24 mois ≈ 5,3 M FCFA
...

Sheet Scénario lean 5M
B2: Scénario lean — levée 5 M FCFA + tranche 2 conditionnelle
B3: Toutes les valeurs en milliers de FCFA (k). Onglet autonome — ne modifie pas les autres onglets.
B5: Hypothèses lean
B6: Levée tranche 1 : 5 000 k à la constitution (M1). Tranche 2 conditionnelle : 3 000 k appelée à M4 si jalons atteints (5 véhicules actifs, premières courses facturées). M6 serait trop tard : le creux de trésorerie tombe à M4-M5.
B7: Expert-comptable négocié 1 200 k payé en 3 tranches (M1/M2/M3). Juriste = fondateur, 300 k (contrats spéciaux, M3).
B8: CAPEX étalé : frais véhicule (habillage 30 k + kit 10 k + inspection 6 k = 46 k/véh) payés au fil de l'onboarding. Photoshoot M4, vidéo promo M5.
B9: Marketing lean : 0 en M1-M2 (pré-lancement), 300 k/mois M3-M12, 500 k/mois en An 2. Caution bureau 2 mois (200 k).
B10: OPEX : salarié déclaré 116,4 k/mois (coût employeur charges incluses), pas de rétainer juriste. Ops manager (200 k) + Parakou (125 k) décalés à M19.
B11: Recettes et montée en flotte identiques aux onglets existants (0 -> 25 véh An 1 à 70 k/véh, 25 -> 30 véh An 2 à 100-140 k/véh).
B12: Fiscalité : hypothèse label startup obtenu (IS = 0 en An 1-2). ADR : encaissements M1-M6 (1 000 k), remboursements M15-M20 (calendrier onglet Cash flow ADR).
B14: Flux (k FCFA) | C14: M1 | D14: M2 | E14: M3 | F14: M4 | G14: M5 | H14: M6 | I14: M7 | J14: M8 | K14: M9 | L14: M10 | M14: M11 | N14: M12 | O14: M13 | P14: M14 | Q14: M15 | R14: M16 | S14: M17 | T14: M18 | U14: M19 | V14: M20 | W14: M21 | X14: M22 | Y14: M23 | Z14: M24 | AA14: Total
B15: Levée capital — tranche 1 | C15: 5000 | D15: 0 | E15: 0 | F15: 0 | G15: 0 | H15: 0 | I15: 0 | J15: 0 | K15: 0 | L15: 0 | M15: 0 | N15: 0 | O15: 0 | P15: 0 | Q15: 0 | R15: 0 | S15: 0 | T15: 0 | U15: 0 | V15: 0 | W15: 0 | X15: 0 | Y15: 0 | Z15: 0 | AA15: =SUM(C15:Z15)
B16: Levée capital — tranche 2 (conditionnelle M4) | C16: 0 | D16: 0 | E16: 0 | F16: 3000 | G16: 0 | H16: 0 | I16: 0 | J16: 0 | K16: 0 | L16: 0 | M16: 0 | N16: 0 | O16: 0 | P16: 0 | Q16: 0 | R16: 0 | S16: 0 | T16: 0 | U16: 0 | V16: 0 | W16: 0 | X16: 0 | Y16: 0 | Z16: 0 | AA16: =SUM(C16:Z16)
B17: ADR encaissées | C17: 300 | D17: 200 | E17: 200 | F17: 100 | G17: 100 | H17: 100 | I17: 0 | J17: 0 | K17: 0 | L17: 0 | M17: 0 | N17: 0 | O17: 0 | P17: 0 | Q17: 0 | R17: 0 | S17: 0 | T17: 0 | U17: 0 | V17: 0 | W17: 0 | X17: 0 | Y17: 0 | Z17: 0 | AA17: =SUM(C17:Z17)
B18: Recettes plateforme | C18: 0 | D18: 0 | E18: 210 | F18: 350 | G18: 490 | H18: 700 | I18: 840 | J18: 910 | K18: 1050 | L18: 1190 | M18: 1400 | N18: 1750 | O18: 2500 | P18: 3120 | Q18: 3510 | R18: 3920 | S18: 4060 | T18: 4200 | U18: 4200 | V18: 4200 | W18: 4200 | X18: 4200 | Y18: 4200 | Z18: 4200 | AA18: =SUM(C18:Z18)
B19: CAPEX étalé | C19: -1125 | D19: -850 | E19: -1238 | F19: -292 | G19: -392 | H19: -138 | I19: -92 | J19: -46 | K19: -92 | L19: -92 | M19: -138 | N19: -230 | O19: 0 | P19: 0 | Q19: 0 | R19: 0 | S19: 0 | T19: 0 | U19: 0 | V19: 0 | W19: 0 | X19: 0 | Y19: 0 | Z19: 0 | AA19: =SUM(C19:Z19)
B20: OPEX lean | C20: -634.6 | D20: -634.6 | E20: -934.6 | F20: -934.6 | G20: -934.6 | H20: -934.6 | I20: -946.6 | J20: -946.6 | K20: -946.6 | L20: -946.6 | M20: -946.6 | N20: -946.6 | O20: -1146.6 | P20: -1146.6 | Q20: -1146.6 | R20: -1146.6 | S20: -1146.6 | T20: -1146.6 | U20: -1471.6 | V20: -1471.6 | W20: -1471.6 | X20: -1471.6 | Y20: -1471.6 | Z20: -1471.6 | AA20: =SUM(C20:Z20)
B21: Remboursements ADR | C21: 0 | D21: 0 | E21: 0 | F21: 0 | G21: 0 | H21: 0 | I21: 0 | J21: 0 | K21: 0 | L21: 0 | M21: 0 | N21: 0 | O21: 0 | P21: 0 | Q21: -300 | R21: -200 | S21: -200 | T21: -100 | U21: -100 | V21: -100 | W21: 0 | X21: 0 | Y21: 0 | Z21: 0 | AA21: =SUM(C21:Z21)
B22: Flux net du mois | C22: =SUM(C15:C21) | D22: =SUM(D15:D21) | E22: =SUM(E15:E21) | F22: =SUM(F15:F21) | G22: =SUM(G15:G21) | H22: =SUM(H15:H21) | I22: =SUM(I15:I21) | J22: =SUM(J15:J21) | ... Z22: =SUM(Z15:Z21) | AA22: =SUM(C22:Z22)
B23: TRÉSORERIE FIN DE MOIS | C23: =C22 | D23: =C23+D22 | E23: =D23+E22 | F23: =E23+F22 | G23: =F23+G22 | H23: =G23+H22 | I23: =H23+I22 | J23: =I23+J22 | K23: =J23+K22 | ... Z23: =Y23+Z22
B25: Synthèse
B26: AVEC tranche 2 (3 000 k à M4) : point bas de trésorerie = +493 k à M3 — VIABLE. Fin M24 = +32 279 k.
B27: SANS tranche 2 (5 000 k seuls) : point bas = -1 574 k à M8 — NON VIABLE (trésorerie négative de M4 à M12). Fin M24 = +29 279 k.
B28: Conclusion : 5 M seuls ne suffisent PAS, même en mode lean. La tranche 2 conditionnelle de 3 M, appelable dès M4 et engagée au Protocole d'Accord, est indispensable.
B29: Alternative : réduire la cible An 1 a un impact direct sur les recettes — ne pas chercher l'équilibre en coupant l'onboarding, c'est lui qui crée les recettes.

Sheet Scénario ultra-lean 3M
B2: Scénario ultra-lean — levée 3 M FCFA, charges au strict minimum
B3: Toutes les valeurs en milliers de FCFA (k). Onglet autonome — ne modifie pas les autres onglets.
B5: Les coupes par rapport au scénario lean 5M — à valider
B6: 1. BUREAU DIFFÉRÉ À M7 (au lieu de M0) : 6 mois en home office + rendez-vous chez partenaires/coworking à la journée. Économie ~1,7 M sur le 1er semestre. Le bureau ouvre quand les recettes tournent (M7).
B7: 2. SALARIÉ DIFFÉRÉ À M7 : secrétariat/support assurés par le fondateur les 6 premiers mois. Économie ~700 k.
B8: 3. MARKETING TERRAIN UNIQUEMENT AN 1 : 100 k/mois dès M3 (flyers, parrainage, activation chauffeurs) — pas d'ads média avant M13. Croissance portée par le bouche-à-oreille et le corridor.
B9: 4. FONDATEUR NON RÉMUNÉRÉ comme juriste (économie 300 k) — rédige lui-même les contrats, validation ponctuelle externe si besoin.
B10: 5. COMPTABLE ALLÉGÉ : 30 k/mois an 1 (tenue légère négociée avec l'expert-comptable), 40 k/mois an 2.
B11: 6. VIDÉO PROMO ET PHOTOSHOOT PRO REPORTÉS à M8+, autofinancés par les recettes. Lancement avec photos légères (50 k) + événement modeste (150 k).
B12: 7. Community manager mi-temps 50 k/mois an 1 (75 k an 2). Support client 25 k/mois an 1 (50 k an 2).
B13: 8. Expert-comptable négocié 1,2 M en 3 tranches (M1/M2/M3). ANATT 300 k (M2). Charte visuelle légère 50 k (logo et plaquette déjà faits).
B14: 9. Mise en service véhicules ~60 k/véh moyen (inspection + habillage + kit + traceur) au fil de l'onboarding — financée par les ADR encaissées (75/100/125 k par engin).
B15: Recettes et montée en flotte INCHANGÉES (0 → 25 véh an 1 à 70 k/véh, 25 → 30 an 2 à 100-140 k/véh) : on coupe les charges, jamais le moteur de revenus.
B17: Flux (k FCFA) | C17: M1 | D17: M2 | E17: M3 | F17: M4 | G17: M5 | H17: M6 | I17: M7 | J17: M8 | K17: M9 | L17: M10 | M17: M11 | N17: M12 | O17: M13 | P17: M14 | Q17: M15 | R17: M16 | S17: M17 | T17: M18 | U17: M19 | V17: M20 | W17: M21 | X17: M22 | Y17: M23 | Z17: M24 | AA17: Total
B18: Levée capital (3 M, unique) | C18: 3000 | D18: 0 | E18: 0 | F18: 0 | G18: 0 | H18: 0 | I18: 0 | J18: 0 | K18: 0 | L18: 0 | M18: 0 | N18: 0 | O18: 0 | P18: 0 | Q18: 0 | R18: 0 | S18: 0 | T18: 0 | U18: 0 | V18: 0 | W18: 0 | X18: 0 | Y18: 0 | Z18: 0 | AA18: =SUM(C18:Z18)
B19: ADR encaissées | C19: 300 | D19: 200 | E19: 200 | F19: 100 | G19: 100 | H19: 100 | I19: 0 | J19: 0 | K19: 0 | L19: 0 | M19: 0 | N19: 0 | O19: 0 | P19: 0 | Q19: 0 | R19: 0 | S19: 0 | T19: 0 | U19: 0 | V19: 0 | W19: 0 | X19: 0 | Y19: 0 | Z19: 0 | AA19: =SUM(C19:Z19)
B20: Recettes plateforme | C20: 0 | D20: 0 | E20: 210 | F20: 350 | G20: 490 | H20: 700 | I20: 840 | J20: 910 | K20: 1050 | L20: 1190 | M20: 1400 | N20: 1750 | O20: 2500 | P20: 3120 | Q20: 3510 | R20: 3920 | S20: 4060 | T20: 4200 | U20: 4200 | V20: 4200 | W20: 4200 | X20: 4200 | Y20: 4200 | Z20: 4200 | AA20: =SUM(C20:Z20)
B21: CAPEX ultra-lean étalé | C21: -400 | D21: -750 | E21: -780 | F21: -120 | G21: -120 | H21: -180 | I21: -520 | J21: -60 | K21: -120 | L21: -120 | M21: -180 | N21: -300 | O21: 0 | P21: 0 | Q21: 0 | R21: 0 | S21: 0 | T21: 0 | U21: 0 | V21: 0 | W21: 0 | X21: 0 | Y21: 0 | Z21: 0 | AA21: =SUM(C21:Z21)
B22: OPEX ultra-lean | C22: -112 | D22: -112 | E22: -344 | F22: -344 | G22: -344 | H22: -344 | I22: -622 | J22: -622 | K22: -622 | L22: -622 | M22: -622 | N22: -622 | O22: -900 | P22: -900 | Q22: -900 | R22: -900 | S22: -900 | T22: -900 | U22: -1225 | V22: -1225 | W22: -1225 | X22: -1225 | Y22: -1225 | Z22: -1225 | AA22: =SUM(C22:Z22)
B23: Remboursements ADR | C23: 0 | D23: 0 | E23: 0 | F23: 0 | G23: 0 | H23: 0 | I23: 0 | J23: 0 | K23: 0 | L23: 0 | M23: 0 | N23: 0 | O23: 0 | P23: 0 | Q23: -300 | R23: -200 | S23: -200 | T23: -100 | U23: -100 | V23: -100 | W23: 0 | X23: 0 | Y23: 0 | Z23: 0 | AA23: =SUM(C23:Z23)
B24: Flux net du mois | C24: =SUM(C18:C23) | D24: =SUM(D18:D23) | E24: =SUM(E18:E23) | F24: =SUM(F18:F23) | G24: =SUM(G18:G23) | H24: =SUM(H18:H23) | I24: =SUM(I18:I23) | J24: =SUM(J18:J23) | ... Z24: =SUM(Z18:Z23) | AA24: =SUM(C24:Z24)
B25: TRÉSORERIE FIN DE MOIS | C25: =C24 | D25: =C25+D24 | E25: =D25+E24 | F25: =E25+F24 | G25: =F25+G24 | H25: =G25+H24 | I25: =H25+I24 | J25: =I25+J24 | K25: =J25+K24 | ... Z25: =Y25+Z24
B27: Synthèse
B28: Point bas de trésorerie : +1 398 k à M4 — la caisse ne passe JAMAIS sous zéro sans tranche 2.
B29: Trésorerie fin M12 : +3 908 k · fin M24 : +36 668 k.
B30: OPEX an 1 : 5 332 k (vs 10 692 k en lean 5M) · CAPEX an 1 : 3 650 k (vs 4 725 k).
B31: Bonus gouvernance : capital 20 M IP + 3 M numéraire = 23 M → part fondateur 87 %. Ticket investisseur 1 M = 4,3 % du capital.
B32: CONDITIONS DE SURVIE : le fondateur porte seul secrétariat + support + juridique pendant 6 mois, et la flotte doit suivre la montée prévue (3 véh à M3, 10 à M6). Si l'onboarding glisse de 2 mois, prévoir soit un apport complémentaire, soit décaler bureau/salarié d'autant.
B33: Sensibilité : recettes −30 % sur l'an 1 → point bas ≈ +400 k à M7 — ça passe encore, de justesse. Recettes −50 % → négatif à M7 : liste d'attente de secours (apport, prêt court) à prévoir.

Sheet Autorisations ANATT
B2: Autorisations ANATT — relevé terrain (2026-07-24)
B3: Valeurs en FCFA. Onglet autonome — ne modifie pas les autres onglets.
B5: A · Frais de constitution / première autorisation (one-time, M1-M3)
B6: Poste | D6: Montant | E6: Note
B7: Casier judiciaire + certificat de nationalité | D7: 6000 | E7: Une fois
B8: Déclaration d'existence | D8: 10000 | E8: Une fois
B9: Autorisation transporteur + inscription registre national | D9: 280000 | E9: ⚠️ RENOUVELABLE CHAQUE ANNÉE (voir bloc B)
B10: Attestation fiscale — CCIB 20k + ORTB 4k + Follow 50k + Main d'œuvre 70k | D10: 144000 | E10: À renouveler chaque année
B11: Acompte IS (minimum de perception) | D11: 62500 | E11: Label startup mis de côté → IS dû. ~250k/an au total (min. perception)
B12: IRF — 12 % du loyer (à charge TamCar, décision Terence) | D12: 144000 | E12: Hypothèse loyer 1,2 M/an × 12 %. À confirmer annuel/mensuel
B13: Sous-total constitution | D13: =SUM(D7:D12)
B15: B · Charges récurrentes annuelles (dès année 2, renouvellements)
B16: Poste | D16: Montant/an | E16: Note
B17: Renouvellement autorisation transporteur | D17: 280000 | E17: Chaque année
B18: Renouvellement attestation fiscale | D18: 144000 | E18: CCIB + ORTB + Follow + Main d'œuvre
B19: IRF annuel (12 % loyer) | D19: 144000 | E19: À charge TamCar
B20: Minimum IS (acomptes) | D20: 250000 | E20: ~250k/an tant que déficitaire (min. perception)
B21: Sous-total annuel | D21: =SUM(D17:D20)
B23: C · Par véhicule
B24: Poste | D24: Montant | E24: Qui paie
B25: Carte d'autorisation de transport / véhicule | D25: 3000 | E25: TamCar (ou refacturé concess) — pièces fournies par concess
B26: Tracker GPS ANATT — voiture 196k / moto 139k / tricycle 139k (an 1) | D26: 0 | E26: CONCESSIONNAIRE — en option, à ses risques. HORS budget TamCar
B28: D · Impact sur le scénario ultra-lean 3M
B30: Le scénario 3M budgétait déjà ANATT à 300 000. Le coût réel constitution (bloc A) ≈ 646 500.
B31: → Surcoût an 1 vs budget : ~346 500 FCFA. Nouveau point bas trésorerie ≈ +1 050 k à M4 (était +1 398 k) — RESTE POSITIF, viable.
B32: En année 2, +818 000 de charges récurrentes ANATT (bloc B) s'ajoutent à l'OPEX An 2. La trésorerie fin An 2 reste largement positive (>30 M dans la projection).
B33: Trackers GPS ANATT : sortis du budget TamCar (charge concessionnaire, en option). Économie ~2 M an 1 vs l'hypothèse où TamCar les aurait payés.
B34: À faire confirmer par l'expert-comptable : IRF (annuel vs mensuel), périodicité exacte du renouvellement, minimum IS applicable.
