Workbook

Sheet Résumé
A1: TamCar — Résultat complet : démarrage, recettes, charges, marge, résultat (FCFA)
A2: Flotte : 1 tricycle + 5 motos + 9 voitures mises à disposition (6 Essentiel, 3 Confort). Recettes aux planchers de Mayeul. Levée de 15 M. Lancement en janvier 2027 (mois 1).
A4: Chiffres clés | B4: Année 1 | C4: Année 2 | D4: Année 3 | E4: Total 3 ans
A5: Démarrage (mois 0, avant l'année 1) | B5: =-Démarrage!B12 -> -4550000
A6: Recettes de TamCar | B6: =Résultat!B6 -> 13104173 | C6: =Résultat!C6 -> 10682880 | D6: =Résultat!D6 -> 10233600 | E6: =Résultat!E6 -> 34020653
A7: Charges d'exploitation (fonctionnement + mise en circulation) | B7: =Résultat!B7+Résultat!B8 -> -9105870 | C7: =Résultat!C7+Résultat!C8 -> -10616870 | D7: =Résultat!D7+Résultat!D8 -> -9716870 | E7: =Résultat!E7+Résultat!E8 -> -29439610
A8: Excédent brut d'exploitation | B8: =Résultat!B9 -> 3998303.3 | C8: =Résultat!C9 -> 66010 | D8: =Résultat!D9 -> 516730 | E8: =Résultat!E9 -> 4581043.3
A9: Amortissements et frais de démarrage | B9: =Résultat!B10+Résultat!B11 -> -6275000 | C9: =Résultat!C10+Résultat!C11 -> -850000 | D9: =Résultat!D10+Résultat!D11 -> -850000 | E9: =Résultat!E10+Résultat!E11 -> -7975000
A10: Résultat net — modèle | B10: =Résultat!B14 -> -2276696.7 | C10: =Résultat!C14 -> -783990 | D10: =Résultat!D14 -> -333270 | E10: =Résultat!E14 -> -3393956.7
A11: Gadgets et gestes commerciaux (à confirmer) | B11: =Résultat!B17+Résultat!B18 -> -695000 | C11: =Résultat!C17+Résultat!C18 -> -790000 | D11: =Résultat!D17+Résultat!D18 -> -790000 | E11: =Résultat!E17+Résultat!E18 -> -2275000
A12: Résultat net après charges à confirmer | B12: =Résultat!B19 -> -2971696.7 | C12: =Résultat!C19 -> -1573990 | D12: =Résultat!D19 -> -1123270 | E12: =Résultat!E19 -> -5668956.7
A13: Variation de la caisse (démarrage inclus en année 1) | B13: =Résultat!B31 -> -4386280 | C13: =Résultat!C31 -> -24406.667 | D13: =Résultat!D31 -> 516730 | E13: =Résultat!E31 -> -3893956.7
A14: Caisse en fin d'année (levée comprise) | B14: =Résultat!B33 -> 10613720 | C14: =Résultat!C33 -> 10589313 | D14: =Résultat!D33 -> 11106043
A15: Marge d'exploitation (excédent brut ÷ recettes) | B15: =IF(B6=0,0,B8/B6) -> 0.30511679 | C15: =IF(C6=0,0,C8/C6) -> 0.0061790454 | D15: =IF(D6=0,0,D8/D6) -> 0.050493472 | E15: =IF(E6=0,0,E8/E6) -> 0.13465477
A17: Marge directe par catégorie, année 1
A18: Catégorie | B18: Recettes | C18: Marge directe | D18: Taux de marge | E18: Résultat par catégorie
A19: Motos (5) | B19: =Marge!B6 -> 3737500 | C19: =Marge!B11 -> 222500 | D19: =Marge!B12 -> 0.059531773 | E19: =Marge!B14 -> -1653854.8
A20: Tricycle (1) | B20: =Marge!C6 -> 1320583.3 | C20: =Marge!C11 -> 511916.67 | D20: =Marge!C12 -> 0.38764435 | E20: =Marge!C14 -> -151062.02
A21: Voitures Essentiel (6) | B21: =Marge!D6 -> 4951440 | C21: =Marge!D11 -> 4277520 | D21: =Marge!D12 -> 0.86389414 | E21: =Marge!D14 -> 1791725.2
A22: Voitures Confort (3) | B22: =Marge!E6 -> 3094650 | C22: =Marge!E11 -> 2673450 | D22: =Marge!E12 -> 0.86389414 | E22: =Marge!E14 -> 1119828.3
A23: Total | B23: =Marge!F6 -> 13104173 | C23: =Marge!F11 -> 7685386.7 | D23: =Marge!F12 -> 0.5864839 | E23: =Marge!F14 -> 1106636.7
A25: Comment lire ce classeur
A26: Résultat (vue économique) : l'achat des véhicules est étalé (moto 12 mois, tricycle 36 mois), les frais de démarrage sont passés en charges et le matériel est amorti sur 36 mois ; la caution du bureau n'est pas une charge. La caisse compte, elle, les décaissements réels : voir « Passage du résultat à la caisse » dans la feuille Résultat (contrôle à 0).
A27: Recettes aux planchers : seules les courses jusqu'au plancher de Mayeul sont comptées. Tout volume au-dessus du plancher s'ajoute aux recettes. Le premier mois de lancement compte pour moitié.
A28: Charges à confirmer (gadgets des meilleurs, gestes commerciaux) : hypothèses de travail, modifiables dans Hypothèses (lignes 90 à 92). Les mettre à 0 les exclut ; le « résultat net — modèle » ne les contient pas.
A29: Non inclus : frais FeexPay (1,7 % payés par le client en plus), frais Mobile Money des retraits chauffeur (à décider), manque éventuel au rachat NSIA, forfait internet des chauffeurs (idée non décidée), charges sociales, entretien (à la charge du conducteur), bonus de performance (neutre aux planchers).
A30: Cellules en bleu sur fond jaune (feuille Hypothèses) : à modifier ; tout le reste se recalcule. Les achats de véhicules des mois suivants se saisissent dans la feuille Mensuel, lignes 7 et 8.

Sheet Hypothèses
A1: TamCar — Hypothèses des charges (FCFA)
A2: Cellules en BLEU sur fond jaune : à modifier. Tout le reste se recalcule (feuilles Mensuel et Synthèse).
A4: Flotte achetée au mois 1 (les achats des mois suivants se saisissent dans la feuille Mensuel, lignes 7 et 8)
A5: Tricycles thermiques achetés au mois 1 | B5: 1 | C5: Formule retenue : 1 tricycle + 5 motos
A6: Motos électriques achetées au mois 1 | B6: 5 | C6: Formule retenue : 1 tricycle + 5 motos
A8: Achat des véhicules
A9: Prix d'un tricycle thermique | B9: 1550000 | C9: Prix donné par Terence
A10: Acompte à l'achat du tricycle (% du prix) | B10: 0.3 | C10: 30 % comptant : à négocier avec le fournisseur
A11: Durée du solde du tricycle (mois) | B11: 12 | C11: Solde en 12 mensualités sans intérêt : à négocier, pas encore accordé
A12: Prix d'une moto électrique (comptant) | B12: 475000 | C12: Prix comptant donné par Terence (500 000 au catalogue)
A14: Mise en circulation (par véhicule)
A15: Assurance + droit taxi + visite technique, tricycle (par an) | B15: 75000 | C15: Plafond « tout compris » donné par Terence ; payé à l'achat puis à chaque anniversaire (36 mois)
A16: Assurance + droit taxi + visite technique, moto (par an) | B16: 50000 | C16: Hypothèse du plan, à confirmer ; payé à l'achat (moto cédée au conducteur à 12 mois)
A17: Tracker GPS tricycle, première année | B17: 139000 | C17: Relevé de Terence du 24/07/2026
A18: Tracker GPS tricycle, renouvellement annuel | B18: 89000 | C18: Relevé de Terence ; payé aux mois 13 et 25 tant que TamCar est propriétaire
A19: Tracker GPS moto, première année | B19: 139000 | C19: Relevé de Terence ; pas de renouvellement (moto cédée à 12 mois)
A21: Démarrage (mois 0)
A22: Formalisation de la société | B22: 1500000 | C22: Plan d'affaires, charges de démarrage arbitrées avec Terence
A23: ANATT (autorisation de transporteur) | B23: 300000 | C23: Plan d'affaires, charges de démarrage arbitrées avec Terence
A24: Juriste (contrats) | B24: 100000 | C24: Plan d'affaires, charges de démarrage arbitrées avec Terence
A25: Bureau de Cotonou (caution, aménagement) | B25: 500000 | C25: Plan d'affaires, charges de démarrage arbitrées avec Terence
A26: Matériel informatique et mobilier (2 bureaux) | B26: 1000000 | C26: Plan d'affaires, charges de démarrage arbitrées avec Terence
A27: Marketing de lancement (photo, vidéo, sponsoring) | B27: 1000000 | C27: Plan d'affaires, charges de démarrage arbitrées avec Terence
A28: Graphisme | B28: 150000 | C28: Plan d'affaires, charges de démarrage arbitrées avec Terence
A30: Fonctionnement (par mois, sauf indication)
A31: Secrétaire | B31: 100000 | C31: Plan d'affaires
A32: Infrastructure technique | B32: 75000 | C32: Plan d'affaires ; payée dès le mois 1
A33: Développeur | B33: 200000 | C33: Plan d'affaires
A34: … à partir du mois | B34: 13 | C34: Payé dès le mois 13
A35: Outil de développement (Claude Code) | B35: 75000 | C35: Plan d'affaires ; mois 1 à 12, ensuite inclus dans la rémunération du développeur
A36: Électricité et eau | B36: 100000 | C36: Plan d'affaires
A37: Loyer du bureau de Cotonou | B37: 50000 | C37: Plan d'affaires
A38: Assurance multirisque professionnelle | B38: 50000 | C38: Plan d'affaires
A39: Comptable (par trimestre, mois 3, 6, 9…) | B39: 75000 | C39: Plan d'affaires
A40: Juriste (par trimestre, mois 3, 6, 9…) | B40: 50000 | C40: Plan d'affaires
A41: Promotion de lancement (par mois) | B41: 100000 | C41: Plan d'affaires
A42: … jusqu'au mois | B42: 6 | C42: Mois 1 à 6
... A51: Patente : taux sur la valeur locative annuelle du bureau | B51: 0.17 | C51: Cotonou : 17 % (loyer × 12)
A53: Financement
A54: Levée de fonds | B54: 15000000 | C54: Plan d'affaires : 15 M
...

Sheet Démarrage
A1: TamCar — Démarrage : ce qui est dépensé avant le lancement (mois 0), FCFA
A2: Montants repris de la feuille Hypothèses. Le traitement indiqué est celui du résultat (vue économique) ; en caisse, tout est décaissé au mois 0.
A4: Poste | B4: Montant | C4: Nature | D4: Traitement dans le résultat | E4: Passé en charges | F4: Immobilisé | G4: Amorti par an
A5: Formalisation de la société | B5: =Hypothèses!B22 -> 1500000 | C5: Frais juridiques | D5: Charge de l'an 1 | E5: =B5 -> 1500000 | F5: 0 | G5: 0
A6: ANATT (autorisation de transporteur) | B6: =Hypothèses!B23 -> 300000 | C6: Autorisation administrative | D6: Charge de l'an 1 (renouvelée chaque année) | E6: =B6 -> 300000 | F6: 0 | G6: 0
A7: Juriste (contrats) | B7: =Hypothèses!B24 -> 100000 | C7: Honoraires | D7: Charge de l'an 1 | E7: =B7 -> 100000 | F7: 0 | G7: 0
A8: Bureau de Cotonou (caution, aménagement) | B8: =Hypothèses!B25 -> 500000 | C8: Dépôt de garantie et aménagement | D8: Ni charge ni amortissement (simplification : à préciser avec le comptable) | E8: 0 | F8: =B8 -> 500000 | G8: 0
A9: Matériel informatique et mobilier (2 bureaux) | B9: =Hypothèses!B26 -> 1000000 | C9: Immobilisation | D9: Amorti sur la durée de la feuille Hypothèses (36 mois) | E9: 0 | F9: =B9 -> 1000000 | G9: =B9/Hypothèses!$B$87*12 -> 333333.33
A10: Marketing de lancement (photo, vidéo, sponsoring) | B10: =Hypothèses!B27 -> 1000000 | C10: Frais de lancement | D10: Charge de l'an 1 | E10: =B10 -> 1000000 | F10: 0 | G10: 0
A11: Graphisme | B11: =Hypothèses!B28 -> 150000 | C11: Frais de création | D11: Charge de l'an 1 | E11: =B11 -> 150000 | F11: 0 | G11: 0
A12: TOTAL DU DÉMARRAGE | B12: =SUM(B5:B11) -> 4550000 | E12: =SUM(E5:E11) -> 3050000 | F12: =SUM(F5:F11) -> 1500000 | G12: =SUM(G5:G11) -> 333333.33
A14: Financement du démarrage
A15: Levée de fonds | B15: =Hypothèses!B54 -> 15000000
A16: Démarrage | B16: =-B12 -> -4550000
A17: Part de la levée absorbée par le démarrage | B17: =B12/B15 -> 0.30333333
A18: Caisse après le démarrage, avant tout achat de véhicule | B18: =B15+B16 -> 10450000
A20: Mise de départ de la flotte (année 1, décaissements réels)
A21: Tricycles : acompte à l'achat | B21: =Mensuel!C42 -> 465000
A22: Tricycles : mensualités du solde payées en année 1 | B22: =Mensuel!C43 -> 994583.33
A23: Motos : achat comptant | B23: =Mensuel!C44 -> 2375000
A24: Assurance, droit taxi, visite technique (tricycles et motos) | B24: =Mensuel!C48+Mensuel!C49 -> 325000
A25: Trackers GPS (tricycles et motos) | B25: =Mensuel!C50+Mensuel!C51 -> 834000
A26: Total flotte, année 1 | B26: =SUM(B21:B25) -> 4993583.3
A28: Les voitures (6 Essentiel, 3 Confort) appartiennent à Afrik Group : assurance, trackers et entretien à la charge du propriétaire. TamCar rembourse au mois 13 l'avance de 100 000 F par voiture.

Sheet Recettes
A1: TamCar — Recettes de TamCar, FCFA (aux planchers de Mayeul : aucune course au-dessus du plancher n'est comptée)
A2: Le premier mois de lancement compte pour moitié. Source : feuille Mensuel.
A4: Recettes de TamCar | B4: Année 1 | C4: Année 2 | D4: Année 3 | E4: Total 3 ans
A5: Tricycle (1) | B5: =Mensuel!C58 -> 1320583.3 | C5: =Mensuel!D58 -> 1352000 | D5: =Mensuel!E58 -> 1352000 | E5: =SUM(B5:D5) -> 4024583.3
A6: Motos (5) | B6: =Mensuel!C59 -> 3737500 | C6: =Mensuel!D59 -> 1300000 | D6: =Mensuel!E59 -> 1300000 | E6: =SUM(B6:D6) -> 6337500
A7: Voitures Essentiel (6) | B7: =Mensuel!C60 -> 4951440 | C7: =Mensuel!D60 -> 4942080 | D7: =Mensuel!E60 -> 4492800 | E7: =SUM(B7:D7) -> 14386320
A8: Voitures Confort (3) | B8: =Mensuel!C61 -> 3094650 | C8: =Mensuel!D61 -> 3088800 | D8: =Mensuel!E61 -> 3088800 | E8: =SUM(B8:D8) -> 9272250
A9: TOTAL DES RECETTES | B9: =SUM(B5:B8) -> 13104173 | C9: =SUM(C5:C8) -> 10682880 | D9: =SUM(D5:D8) -> 10233600 | E9: =SUM(E5:E8) -> 34020653
A10: Évolution par rapport à l'année précédente | C10: =IF(B9=0,0,C9/B9-1) -> -0.18477269 | D10: =IF(C9=0,0,D9/C9-1) -> -0.042056075
A11: Recette moyenne par mois | B11: =B9/12 -> 1092014.4 | C11: =C9/12 -> 890240 | D11: =D9/12 -> 852800
A13: Volume de courses et part de TamCar
A14: Volume de courses dans l'application (au plancher) | B14: Année 1 | C14: Année 2 | D14: Année 3 | E14: Total 3 ans
A15: Tricycle (1) | B15: =Mensuel!C80 -> 2491666.7 | C15: =Mensuel!D80 -> 2600000 | D15: =Mensuel!E80 -> 2600000 | E15: =SUM(B15:D15) -> 7691666.7
A16: Motos (5) | B16: =Mensuel!C81 -> 6229166.7 | C16: =Mensuel!D81 -> 6500000 | D16: =Mensuel!E81 -> 6500000 | E16: =SUM(B16:D16) -> 19229167
A17: Voitures Essentiel (6) | B17: =Mensuel!C82 -> 21528000 | C17: =Mensuel!D82 -> 22464000 | D17: =Mensuel!E82 -> 22464000 | E17: =SUM(B17:D17) -> 66456000
A18: Voitures Confort (3) | B18: =Mensuel!C83 -> 13455000 | C18: =Mensuel!D83 -> 14040000 | D18: =Mensuel!E83 -> 14040000 | E18: =SUM(B18:D18) -> 41535000
A19: VOLUME TOTAL | B19: =SUM(B15:B18) -> 43703833 | C19: =SUM(C15:C18) -> 45604000 | D19: =SUM(D15:D18) -> 45604000 | E19: =SUM(E15:E18) -> 1.3491183e+08
A20: Recette de TamCar en % du volume | B20: =IF(B19=0,0,B9/B19) -> 0.29984036 | C20: =IF(C19=0,0,C9/C19) -> 0.23425314 | D20: =IF(D19=0,0,D9/D19) -> 0.22440137 | E20: =IF(E19=0,0,E9/E19) -> 0.25216953
A21: Part des voitures dans les recettes | B21: =IF(B9=0,0,(B7+B8)/B9) -> 0.61400974 | C21: =IF(C9=0,0,(C7+C8)/C9) -> 0.75175234 | D21: =IF(D9=0,0,(D7+D8)/D9) -> 0.74085366 | E21: =IF(E9=0,0,(E7+E8)/E9) -> 0.69541786
A23: Planchers de recettes retenus (par véhicule et par jour travaillé)
A24: Tricycle : volume de courses | B24: =Hypothèses!B45 -> 8333.3333
A25: Moto : volume de courses | B25: =Hypothèses!B46 -> 4166.6667
A26: Moto : versement minimum à TamCar | B26: =Hypothèses!B75 -> 2500
A27: Voiture Essentiel : recettes | B27: =Hypothèses!B60 -> 12000
A28: Voiture Confort : recettes | B28: =Hypothèses!B61 -> 15000
A29: Jours travaillés par mois | B29: =Hypothèses!B47 -> 26
A31: Recettes de l'année 1, mois par mois
A32: Mois | B32: M1 | C32: M2 | D32: M3 | E32: M4 | F32: M5 | G32: M6 | H32: M7 | I32: M8 | J32: M9 | K32: M10 | L32: M11 | M32: M12 | N32: Année 1
A33: Tricycle (1) | B33: =Mensuel!H58 -> 57416.667 | C33: =Mensuel!I58 -> 114833.33 | D33: =Mensuel!J58 -> 114833.33 | E33: =Mensuel!K58 -> 114833.33 | F33: =Mensuel!L58 -> 114833.33 | G33: =Mensuel!M58 -> 114833.33 | H33: =Mensuel!N58 -> 114833.33 | I33: =Mensuel!O58 -> 114833.33 | ... M33: =Mensuel!S58 -> 114833.33 | N33: =SUM(B33:M33) -> 1320583.3
A34: Motos (5) | B34: =Mensuel!H59 -> 162500 | C34: =Mensuel!I59 -> 325000 | D34: =Mensuel!J59 -> 325000 | E34: =Mensuel!K59 -> 325000 | F34: =Mensuel!L59 -> 325000 | G34: =Mensuel!M59 -> 325000 | H34: =Mensuel!N59 -> 325000 | I34: =Mensuel!O59 -> 325000 | ... M34: =Mensuel!S59 -> 325000 | N34: =SUM(B34:M34) -> 3737500
A35: Voitures Essentiel (6) | B35: =Mensuel!H60 -> 215280 | C35: =Mensuel!I60 -> 430560 | D35: =Mensuel!J60 -> 430560 | E35: =Mensuel!K60 -> 430560 | F35: =Mensuel!L60 -> 430560 | G35: =Mensuel!M60 -> 430560 | H35: =Mensuel!N60 -> 430560 | I35: =Mensuel!O60 -> 430560 | ... M35: =Mensuel!S60 -> 430560 | N35: =SUM(B35:M35) -> 4951440
A36: Voitures Confort (3) | B36: =Mensuel!H61 -> 134550 | C36: =Mensuel!I61 -> 269100 | D36: =Mensuel!J61 -> 269100 | E36: =Mensuel!K61 -> 269100 | F36: =Mensuel!L61 -> 269100 | G36: =Mensuel!M61 -> 269100 | H36: =Mensuel!N61 -> 269100 | I36: =Mensuel!O61 -> 269100 | ... M36: =Mensuel!S61 -> 269100 | N36: =SUM(B36:M36) -> 3094650
A37: TOTAL | B37: =SUM(B33:B36) -> 569746.67 | C37: =SUM(C33:C36) -> 1139493.3 | D37: =SUM(D33:D36) -> 1139493.3 | E37: =SUM(E33:E36) -> 1139493.3 | F37: =SUM(F33:F36) -> 1139493.3 | G37: =SUM(G33:G36) -> 1139493.3 | H37: =SUM(H33:H36) -> 1139493.3 | I37: =SUM(I33:I36) -> 1139493.3 | ... N37: =SUM(N33:N36) -> 13104173

Sheet Charges
A1: TamCar — Charges, FCFA (décaissements réels, comme dans la caisse)
A2: Les amortissements et les charges à confirmer sont en bas : ils servent au résultat, pas à la caisse.
A4: Poste | B4: Démarrage (mois 0) | C4: Année 1 | D4: Année 2 | E4: Année 3 | F4: Total 3 ans
A5: DÉMARRAGE (mois 0)
A6: =Mensuel!A13 -> Formalisation de la société | B6: =Mensuel!B13 -> 1500000 | C6: =Mensuel!C13 -> 0 | D6: =Mensuel!D13 -> 0 | E6: =Mensuel!E13 -> 0 | F6: =Mensuel!F13 -> 1500000
A7: =Mensuel!A14 -> ANATT (autorisation de transporteur) | B7: =Mensuel!B14 -> 300000 | C7: =Mensuel!C14 -> 0 | D7: =Mensuel!D14 -> 0 | E7: =Mensuel!E14 -> 0 | F7: =Mensuel!F14 -> 300000
A8: =Mensuel!A15 -> Juriste (contrats) | B8: =Mensuel!B15 -> 100000 | C8: =Mensuel!C15 -> 0 | D8: =Mensuel!D15 -> 0 | E8: =Mensuel!E15 -> 0 | F8: =Mensuel!F15 -> 100000
A9: =Mensuel!A16 -> Bureau de Cotonou (caution, aménagement) | B9: =Mensuel!B16 -> 500000 | C9: =Mensuel!C16 -> 0 | D9: =Mensuel!D16 -> 0 | E9: =Mensuel!E16 -> 0 | F9: =Mensuel!F16 -> 500000
A10: =Mensuel!A17 -> Matériel informatique et mobilier (2 bureaux) | B10: =Mensuel!B17 -> 1000000 | C10: =Mensuel!C17 -> 0 | D10: =Mensuel!D17 -> 0 | E10: =Mensuel!E17 -> 0 | F10: =Mensuel!F17 -> 1000000
A11: =Mensuel!A18 -> Marketing de lancement (photo, vidéo, sponsoring) | B11: =Mensuel!B18 -> 1000000 | C11: =Mensuel!C18 -> 0 | D11: =Mensuel!D18 -> 0 | E11: =Mensuel!E18 -> 0 | F11: =Mensuel!F18 -> 1000000
A12: =Mensuel!A19 -> Graphisme | B12: =Mensuel!B19 -> 150000 | C12: =Mensuel!C19 -> 0 | D12: =Mensuel!D19 -> 0 | E12: =Mensuel!E19 -> 0 | F12: =Mensuel!F19 -> 150000
A13: Sous-total démarrage | B13: =Mensuel!B20 -> 4550000 | C13: =Mensuel!C20 -> 0 | D13: =Mensuel!D20 -> 0 | E13: =Mensuel!E20 -> 0 | F13: =Mensuel!F20 -> 4550000
A15: FONCTIONNEMENT
A16: =Mensuel!A23 -> Secrétaire | B16: =Mensuel!B23 -> 0 | C16: =Mensuel!C23 -> 1200000 | D16: =Mensuel!D23 -> 1200000 | E16: =Mensuel!E23 -> 1200000 | F16: =Mensuel!F23 -> 3600000
A17: =Mensuel!A24 -> Infrastructure technique | B17: =Mensuel!B24 -> 0 | C17: =Mensuel!C24 -> 900000 | D17: =Mensuel!D24 -> 900000 | E17: =Mensuel!E24 -> 900000 | F17: =Mensuel!F24 -> 2700000
A18: =Mensuel!A25 -> Développeur (dès le mois indiqué dans les hypothèses) | B18: =Mensuel!B25 -> 0 | C18: =Mensuel!C25 -> 0 | D18: =Mensuel!D25 -> 2400000 | E18: =Mensuel!E25 -> 2400000 | F18: =Mensuel!F25 -> 4800000
A19: =Mensuel!A26 -> Outil de développement (Claude Code, mois 1 à 12) | B19: =Mensuel!B26 -> 0 | C19: =Mensuel!C26 -> 900000 | D19: =Mensuel!D26 -> 0 | E19: =Mensuel!E26 -> 0 | F19: =Mensuel!F26 -> 900000
A20: =Mensuel!A27 -> Électricité et eau | B20: =Mensuel!B27 -> 0 | C20: =Mensuel!C27 -> 1200000 | D20: =Mensuel!D27 -> 1200000 | E20: =Mensuel!E27 -> 1200000 | F20: =Mensuel!F27 -> 3600000
A21: =Mensuel!A28 -> Loyer du bureau de Cotonou | B21: =Mensuel!B28 -> 0 | C21: =Mensuel!C28 -> 600000 | D21: =Mensuel!D28 -> 600000 | E21: =Mensuel!E28 -> 600000 | F21: =Mensuel!F28 -> 1800000
A22: =Mensuel!A29 -> Assurance multirisque professionnelle | B22: =Mensuel!B29 -> 0 | C22: =Mensuel!C29 -> 600000 | D22: =Mensuel!D29 -> 600000 | E22: =Mensuel!E29 -> 600000 | F22: =Mensuel!F29 -> 1800000
A23: =Mensuel!A30 -> Comptable (par trimestre) | B23: =Mensuel!B30 -> 0 | C23: =Mensuel!C30 -> 300000 | D23: =Mensuel!D30 -> 300000 | E23: =Mensuel!E30 -> 300000 | F23: =Mensuel!F30 -> 900000
A24: =Mensuel!A31 -> Juriste (par trimestre) | B24: =Mensuel!B31 -> 0 | C24: =Mensuel!C31 -> 200000 | D24: =Mensuel!D31 -> 200000 | E24: =Mensuel!E31 -> 200000 | F24: =Mensuel!F31 -> 600000
A25: =Mensuel!A32 -> Promotion de lancement | B25: =Mensuel!B32 -> 0 | C25: =Mensuel!C32 -> 600000 | D25: =Mensuel!D32 -> 0 | E25: =Mensuel!E32 -> 0 | F25: =Mensuel!F32 -> 600000
A26: =Mensuel!A33 -> Responsable des opérations (3 % du volume, plafonné) | B26: =Mensuel!B33 -> 0 | C26: =Mensuel!C33 -> 1368120 | D26: =Mensuel!D33 -> 1368120 | E26: =Mensuel!E33 -> 1368120 | F26: =Mensuel!F33 -> 4104360
A27: =Mensuel!A34 -> Renouvellement ANATT (mois 13 et 25) | B27: =Mensuel!B34 -> 0 | C27: =Mensuel!C34 -> 0 | D27: =Mensuel!D34 -> 280000 | E27: =Mensuel!E34 -> 280000 | F27: =Mensuel!F34 -> 560000
... A31: =Mensuel!A38 -> Épargne NSIA : postes vacants (TamCar paie la cotisation) | B31: =Mensuel!B38 -> 0 | C31: =Mensuel!C38 -> 78750 | D31: =Mensuel!D38 -> 78750 | E31: =Mensuel!E38 -> 78750 | F31: =Mensuel!F38 -> 236250
A32: Sous-total fonctionnement | B32: =Mensuel!B39 -> 0 | C32: =Mensuel!C39 -> 7946870 | D32: =Mensuel!D39 -> 10452870 | E32: =Mensuel!E39 -> 9552870 | F32: =Mensuel!F39 -> 27952610
A34: ACHAT DES VÉHICULES
A35: =Mensuel!A42 -> Tricycles : acompte à l'achat | B35: =Mensuel!B42 -> 0 | C35: =Mensuel!C42 -> 465000 | D35: =Mensuel!D42 -> 0 | E35: =Mensuel!E42 -> 0 | F35: =Mensuel!F42 -> 465000
A36: =Mensuel!A43 -> Tricycles : mensualités du solde | B36: =Mensuel!B43 -> 0 | C36: =Mensuel!C43 -> 994583.33 | D36: =Mensuel!D43 -> 90416.667 | E36: =Mensuel!E43 -> 0 | F36: =Mensuel!F43 -> 1085000
A37: =Mensuel!A44 -> Motos : achat comptant | B37: =Mensuel!B44 -> 0 | C37: =Mensuel!C44 -> 2375000 | D37: =Mensuel!D44 -> 0 | E37: =Mensuel!E44 -> 0 | F37: =Mensuel!F44 -> 2375000
A38: Sous-total achat des véhicules | B38: =Mensuel!B45 -> 0 | C38: =Mensuel!C45 -> 3834583.3 | D38: =Mensuel!D45 -> 90416.667 | E38: =Mensuel!E45 -> 0 | F38: =Mensuel!F45 -> 3925000
A40: MISE EN CIRCULATION (assurance, droit taxi, visite technique, trackers)
A41: =Mensuel!A48 -> Assurance + droit taxi + visite technique : tricycles (achat, puis anniversaires) | B41: =Mensuel!B48 -> 0 | C41: =Mensuel!C48 -> 75000 | D41: =Mensuel!D48 -> 75000 | E41: =Mensuel!E48 -> 75000 | F41: =Mensuel!F48 -> 225000
A42: =Mensuel!A49 -> Assurance + droit taxi + visite technique : motos (à l'achat) | B42: =Mensuel!B49 -> 0 | C42: =Mensuel!C49 -> 250000 | D42: =Mensuel!D49 -> 0 | E42: =Mensuel!E49 -> 0 | F42: =Mensuel!F49 -> 250000
A43: =Mensuel!A50 -> Trackers GPS : tricycles (1re année, puis renouvellement) | B43: =Mensuel!B50 -> 0 | C43: =Mensuel!C50 -> 139000 | D43: =Mensuel!D50 -> 89000 | E43: =Mensuel!E50 -> 89000 | F43: =Mensuel!F50 -> 317000
A44: =Mensuel!A51 -> Trackers GPS : motos (à l'achat) | B44: =Mensuel!B51 -> 0 | C44: =Mensuel!C51 -> 695000 | D44: =Mensuel!D51 -> 0 | E44: =Mensuel!E51 -> 0 | F44: =Mensuel!F51 -> 695000
A45: Sous-total mise en circulation | B45: =Mensuel!B52 -> 0 | C45: =Mensuel!C52 -> 1159000 | D45: =Mensuel!D52 -> 164000 | E45: =Mensuel!E52 -> 164000 | F45: =Mensuel!F52 -> 1487000
A47: TOTAL DES CHARGES DÉCAISSÉES | B47: =Mensuel!B54 -> 4550000 | C47: =Mensuel!C54 -> 12940453 | D47: =Mensuel!D54 -> 10707287 | E47: =Mensuel!E54 -> 9716870 | F47: =Mensuel!F54 -> 37914610
A48: Contrôle : somme des quatre sous-totaux − total (doit être 0) | B48: =B13+B32+B38+B45-B47 -> 0 | C48: =C13+C32+C38+C45-C47 -> 0 | D48: =D13+D32+D38+D45-D47 -> 0 | E48: =E13+E32+E38+E45-E47 -> 0 | F48: =F13+F32+F38+F45-F47 -> 0
...

Sheet Marge
A1: TamCar — Marge par catégorie de véhicule, FCFA
A2: Marge directe = recettes − amortissement du véhicule − assurance/droits/trackers − part du responsable des opérations (3 % du volume, réparti selon le volume). Les autres charges de fonctionnement sont réparties au prorata des recettes.
A4: ANNÉE 1
A5: Poste | B5: Motos (5) | C5: Tricycle (1) | D5: Voitures Essentiel (6) | E5: Voitures Confort (3) | F5: Total
A6: Recettes de TamCar | B6: =Mensuel!C59 -> 3737500 | C6: =Mensuel!C58 -> 1320583.3 | D6: =Mensuel!C60 -> 4951440 | E6: =Mensuel!C61 -> 3094650 | F6: =SUM(B6:E6) -> 13104173
A7: Amortissement du véhicule | B7: =-Mensuel!C71 -> -2375000 | C7: =-Mensuel!C70 -> -516666.67 | D7: 0 | E7: 0 | F7: =SUM(B7:E7) -> -2891666.7
A8: Assurance, droit taxi, visite technique | B8: =-Mensuel!C49 -> -250000 | C8: =-Mensuel!C48 -> -75000 | D8: 0 | E8: 0 | F8: =SUM(B8:E8) -> -325000
A9: Trackers GPS | B9: =-Mensuel!C51 -> -695000 | C9: =-Mensuel!C50 -> -139000 | D9: 0 | E9: 0 | F9: =SUM(B9:E9) -> -834000
A10: Responsable des opérations (3 % du volume) | B10: =-Mensuel!C33*IF(Mensuel!C84=0,0,Mensuel!C81/Mensuel!C84) -> -195000 | C10: =-Mensuel!C33*IF(Mensuel!C84=0,0,Mensuel!C80/Mensuel!C84) -> -78000 | D10: =-Mensuel!C33*IF(Mensuel!C84=0,0,Mensuel!C82/Mensuel!C84) -> -673920 | E10: =-Mensuel!C33*IF(Mensuel!C84=0,0,Mensuel!C83/Mensuel!C84) -> -421200 | F10: =SUM(B10:E10) -> -1368120
A11: MARGE DIRECTE | B11: =SUM(B6:B10) -> 222500 | C11: =SUM(C6:C10) -> 511916.67 | D11: =SUM(D6:D10) -> 4277520 | E11: =SUM(E6:E10) -> 2673450 | F11: =SUM(F6:F10) -> 7685386.7
A12: Taux de marge directe (% des recettes) | B12: =IF(B6=0,0,B11/B6) -> 0.059531773 | C12: =IF(C6=0,0,C11/C6) -> 0.38764435 | D12: =IF(D6=0,0,D11/D6) -> 0.86389414 | E12: =IF(E6=0,0,E11/E6) -> 0.86389414 | F12: =IF(F6=0,0,F11/F6) -> 0.5864839
A13: Autres charges de fonctionnement (au prorata des recettes) | B13: =-(Mensuel!C39-Mensuel!C33)*IF($F6=0,0,B6/$F6) -> -1876354.8 | C13: =-(Mensuel!C39-Mensuel!C33)*IF($F6=0,0,C6/$F6) -> -662978.68 | D13: =-(Mensuel!C39-Mensuel!C33)*IF($F6=0,0,D6/$F6) -> -2485794.8 | E13: =-(Mensuel!C39-Mensuel!C33)*IF($F6=0,0,E6/$F6) -> -1553621.7 | F13: =SUM(B13:E13) -> -6578750
A14: RÉSULTAT PAR CATÉGORIE (avant démarrage, matériel, gadgets, gestes) | B14: =B11+B13 -> -1653854.8 | C14: =C11+C13 -> -151062.02 | D14: =D11+D13 -> 1791725.2 | E14: =E11+E13 -> 1119828.3 | F14: =F11+F13 -> 1106636.7
A15: Nombre de véhicules (moyenne de l'année) | B15: =AVERAGE(Mensuel!H10:S10) -> 5 | C15: =AVERAGE(Mensuel!H9:S9) -> 1 | D15: =Hypothèses!$B$57 -> 6 | E15: =Hypothèses!$B$58 -> 3 | F15: =SUM(B15:E15) -> 15
A16: Marge directe par véhicule et par jour travaillé | B16: =IF(B15=0,0,B11/(B15*Hypothèses!$B$47*12)) -> 142.62821 | C16: =IF(C15=0,0,C11/(C15*Hypothèses!$B$47*12)) -> 1640.7585 | D16: =IF(D15=0,0,D11/(D15*Hypothèses!$B$47*12)) -> 2285 | E16: =IF(E15=0,0,E11/(E15*Hypothèses!$B$47*12)) -> 2856.25 | F16: =IF(F15=0,0,F11/(F15*Hypothèses!$B$47*12)) -> 1642.1766
A17: Résultat par véhicule et par jour travaillé | B17: =IF(B15=0,0,B14/(B15*Hypothèses!$B$47*12)) -> -1060.1633 | C17: =IF(C15=0,0,C14/(C15*Hypothèses!$B$47*12)) -> -484.17314 | D17: =IF(D15=0,0,D14/(D15*Hypothèses!$B$47*12)) -> 957.11816 | E17: =IF(E15=0,0,E14/(E15*Hypothèses!$B$47*12)) -> 1196.3977 | F17: =IF(F15=0,0,F14/(F15*Hypothèses!$B$47*12)) -> 236.46083
A19: ANNÉE 2
A20: Poste | B20: Motos (5) | C20: Tricycle (1) | D20: Voitures Essentiel (6) | E20: Voitures Confort (3) | F20: Total
A21: Recettes de TamCar | B21: =Mensuel!D59 -> 1300000 | C21: =Mensuel!D58 -> 1352000 | D21: =Mensuel!D60 -> 4942080 | E21: =Mensuel!D61 -> 3088800 | F21: =SUM(B21:E21) -> 10682880
A22: Amortissement du véhicule | B22: =-Mensuel!D71 -> 0 | C22: =-Mensuel!D70 -> -516666.67 | D22: 0 | E22: 0 | F22: =SUM(B22:E22) -> -516666.67
A23: Assurance, droit taxi, visite technique | B23: =-Mensuel!D49 -> 0 | C23: =-Mensuel!D48 -> -75000 | D23: 0 | E23: 0 | F23: =SUM(B23:E23) -> -75000
A24: Trackers GPS | B24: =-Mensuel!D51 -> 0 | C24: =-Mensuel!D50 -> -89000 | D24: 0 | E24: 0 | F24: =SUM(B24:E24) -> -89000
A25: Responsable des opérations (3 % du volume) | B25: =-Mensuel!D33*IF(Mensuel!D84=0,0,Mensuel!D81/Mensuel!D84) -> -195000 | C25: =-Mensuel!D33*IF(Mensuel!D84=0,0,Mensuel!D80/Mensuel!D84) -> -78000 | D25: =-Mensuel!D33*IF(Mensuel!D84=0,0,Mensuel!D82/Mensuel!D84) -> -673920 | E25: =-Mensuel!D33*IF(Mensuel!D84=0,0,Mensuel!D83/Mensuel!D84) -> -421200 | F25: =SUM(B25:E25) -> -1368120
A26: MARGE DIRECTE | B26: =SUM(B21:B25) -> 1105000 | C26: =SUM(C21:C25) -> 593333.33 | D26: =SUM(D21:D25) -> 4268160 | E26: =SUM(E21:E25) -> 2667600 | F26: =SUM(F21:F25) -> 8634093.3
A27: Taux de marge directe (% des recettes) | B27: =IF(B21=0,0,B26/B21) -> 0.85 | C27: =IF(C21=0,0,C26/C21) -> 0.43885602 | D27: =IF(D21=0,0,D26/D21) -> 0.86363636 | E27: =IF(E21=0,0,E26/E21) -> 0.86363636 | F27: =IF(F21=0,0,F26/F21) -> 0.80821776
A28: Autres charges de fonctionnement (au prorata des recettes) | B28: =-(Mensuel!D39-Mensuel!D33)*IF($F21=0,0,B21/$F21) -> -1105523.5 | C28: =-(Mensuel!D39-Mensuel!D33)*IF($F21=0,0,C21/$F21) -> -1149744.5 | D28: =-(Mensuel!D39-Mensuel!D33)*IF($F21=0,0,D21/$F21) -> -4202758.2 | E28: =-(Mensuel!D39-Mensuel!D33)*IF($F21=0,0,E21/$F21) -> -2626723.9 | F28: =SUM(B28:E28) -> -9084750
A29: RÉSULTAT PAR CATÉGORIE (avant démarrage, matériel, gadgets, gestes) | B29: =B26+B28 -> -523.51051 | C29: =C26+C28 -> -556411.12 | D29: =D26+D28 -> 65401.822 | E29: =E26+E28 -> 40876.139 | F29: =F26+F28 -> -450656.67
A30: Nombre de véhicules (moyenne de l'année) | B30: =AVERAGE(Mensuel!T10:AE10) -> 5 | C30: =AVERAGE(Mensuel!T9:AE9) -> 1 | D30: =Hypothèses!$B$57 -> 6 | E30: =Hypothèses!$B$58 -> 3 | F30: =SUM(B30:E30) -> 15
A31: Marge directe par véhicule et par jour travaillé | B31: =IF(B30=0,0,B26/(B30*Hypothèses!$B$47*12)) -> 708.33333 | C31: =IF(C30=0,0,C26/(C30*Hypothèses!$B$47*12)) -> 1901.7094 | D31: =IF(D30=0,0,D26/(D30*Hypothèses!$B$47*12)) -> 2280 | E31: =IF(E30=0,0,E26/(E30*Hypothèses!$B$47*12)) -> 2850 | F31: =IF(F30=0,0,F26/(F30*Hypothèses!$B$47*12)) -> 1844.8917
A32: Résultat par véhicule et par jour travaillé | B32: =IF(B30=0,0,B29/(B30*Hypothèses!$B$47*12)) -> -0.33558366 | C32: =IF(C30=0,0,C29/(C30*Hypothèses!$B$47*12)) -> -1783.369 | D32: =IF(D30=0,0,D29/(D30*Hypothèses!$B$47*12)) -> 34.936871 | E32: =IF(E30=0,0,E29/(E30*Hypothèses!$B$47*12)) -> 43.671089 | F32: =IF(F30=0,0,F29/(F30*Hypothèses!$B$47*12)) -> -96.29416
A34: ANNÉE 3
A35: Poste | B35: Motos (5) | C35: Tricycle (1) | D35: Voitures Essentiel (6) | E35: Voitures Confort (3) | F35: Total
A36: Recettes de TamCar | B36: =Mensuel!E59 -> 1300000 | C36: =Mensuel!E58 -> 1352000 | D36: =Mensuel!E60 -> 4492800 | E36: =Mensuel!E61 -> 3088800 | F36: =SUM(B36:E36) -> 10233600
A37: Amortissement du véhicule | B37: =-Mensuel!E71 -> 0 | C37: =-Mensuel!E70 -> -516666.67 | D37: 0 | E37: 0 | F37: =SUM(B37:E37) -> -516666.67
A38: Assurance, droit taxi, visite technique | B38: =-Mensuel!E49 -> 0 | C38: =-Mensuel!E48 -> -75000 | D38: 0 | E38: 0 | F38: =SUM(B38:E38) -> -75000
A39: Trackers GPS | B39: =-Mensuel!E51 -> 0 | C39: =-Mensuel!E50 -> -89000 | D39: 0 | E39: 0 | F39: =SUM(B39:E39) -> -89000
A40: Responsable des opérations (3 % du volume) | B40: =-Mensuel!E33*IF(Mensuel!E84=0,0,Mensuel!E81/Mensuel!E84) -> -195000 | C40: =-Mensuel!E33*IF(Mensuel!E84=0,0,Mensuel!E80/Mensuel!E84) -> -78000 | D40: =-Mensuel!E33*IF(Mensuel!E84=0,0,Mensuel!E82/Mensuel!E84) -> -673920 | E40: =-Mensuel!E33*IF(Mensuel!E84=0,0,Mensuel!E83/Mensuel!E84) -> -421200 | F40: =SUM(B40:E40) -> -1368120
A41: MARGE DIRECTE | B41: =SUM(B36:B40) -> 1105000 | C41: =SUM(C36:C40) -> 593333.33 | D41: =SUM(D36:D40) -> 3818880 | E41: =SUM(E36:E40) -> 2667600 | F41: =SUM(F36:F40) -> 8184813.3
A42: Taux de marge directe (% des recettes) | B42: =IF(B36=0,0,B41/B36) -> 0.85 | C42: =IF(C36=0,0,C41/C36) -> 0.43885602 | D42: =IF(D36=0,0,D41/D36) -> 0.85 | E42: =IF(E36=0,0,E41/E36) -> 0.86363636 | F42: =IF(F36=0,0,F41/F36) -> 0.79979805
A43: Autres charges de fonctionnement (au prorata des recettes) | B43: =-(Mensuel!E39-Mensuel!E33)*IF($F36=0,0,B36/$F36) -> -1039729.4 | C43: =-(Mensuel!E39-Mensuel!E33)*IF($F36=0,0,C36/$F36) -> -1081318.6 | D43: =-(Mensuel!E39-Mensuel!E33)*IF($F36=0,0,D36/$F36) -> -3593304.9 | E43: =-(Mensuel!E39-Mensuel!E33)*IF($F36=0,0,E36/$F36) -> -2470397.1 | F43: =SUM(B43:E43) -> -8184750
...

Sheet Résultat
A1: TamCar — Compte de résultat et passage à la caisse, FCFA
A2: Vue économique : l'achat des véhicules est étalé, les frais de démarrage sont passés en charges dans l'année 1. Recettes aux planchers de Mayeul.
A4: Poste | B4: Année 1 | C4: Année 2 | D4: Année 3 | E4: Total 3 ans
A5: COMPTE DE RÉSULTAT
A6: Recettes de TamCar (courses) | B6: =Mensuel!C62 -> 13104173 | C6: =Mensuel!D62 -> 10682880 | D6: =Mensuel!E62 -> 10233600 | E6: =SUM(B6:D6) -> 34020653
A7: Charges de fonctionnement | B7: =-Mensuel!C39 -> -7946870 | C7: =-Mensuel!D39 -> -10452870 | D7: =-Mensuel!E39 -> -9552870 | E7: =SUM(B7:D7) -> -27952610
A8: Mise en circulation (assurance, droit taxi, visite technique, trackers) | B8: =-Mensuel!C52 -> -1159000 | C8: =-Mensuel!D52 -> -164000 | D8: =-Mensuel!E52 -> -164000 | E8: =SUM(B8:D8) -> -1487000
A9: EXCÉDENT BRUT D'EXPLOITATION | B9: =B6+B7+B8 -> 3998303.3 | C9: =C6+C7+C8 -> 66010 | D9: =D6+D7+D8 -> 516730 | E9: =SUM(B9:D9) -> 4581043.3
A10: Amortissements (véhicules et matériel) | B10: =-Mensuel!C73 -> -3225000 | C10: =-Mensuel!D73 -> -850000 | D10: =-Mensuel!E73 -> -850000 | E10: =SUM(B10:D10) -> -4925000
A11: Frais de démarrage passés en charges | B11: =-(Mensuel!B74+Mensuel!C74) -> -3050000 | C11: =-Mensuel!D74 -> 0 | D11: =-Mensuel!E74 -> 0 | E11: =SUM(B11:D11) -> -3050000
A12: RÉSULTAT D'EXPLOITATION (modèle) | B12: =B9+B10+B11 -> -2276696.7 | C12: =C9+C10+C11 -> -783990 | D12: =D9+D10+D11 -> -333270 | E12: =SUM(B12:D12) -> -3393956.7
A13: Impôt sur les sociétés (estimation : 30 %, exonéré les premières années, déficits reportés) | B13: =-IF(1<=Hypothèses!$B$89,0,Hypothèses!$B$88*MAX(0,B12)) -> 0 | C13: =-IF(2<=Hypothèses!$B$89,0,Hypothèses!$B$88*MAX(0,C12+MIN(0,B12))) -> 0 | D13: =-IF(3<=Hypothèses!$B$89,0,Hypothèses!$B$88*MAX(0,D12+MIN(0,B12+C12))) -> 0 | E13: =SUM(B13:D13) -> 0
A14: RÉSULTAT NET — MODÈLE (sans charges à confirmer) | B14: =B12+B13 -> -2276696.7 | C14: =C12+C13 -> -783990 | D14: =D12+D13 -> -333270 | E14: =SUM(B14:D14) -> -3393956.7
A16: CHARGES NON ENCORE CONFIRMÉES (hypothèses modifiables dans Hypothèses, lignes 90 à 92)
A17: Gadgets des meilleurs | B17: =-Mensuel!C75 -> -95000 | C17: =-Mensuel!D75 -> -190000 | D17: =-Mensuel!E75 -> -190000 | E17: =SUM(B17:D17) -> -475000
A18: Gestes commerciaux | B18: =-Mensuel!C76 -> -600000 | C18: =-Mensuel!D76 -> -600000 | D18: =-Mensuel!E76 -> -600000 | E18: =SUM(B18:D18) -> -1800000
A19: RÉSULTAT NET APRÈS CHARGES À CONFIRMER | B19: =B14+B17+B18 -> -2971696.7 | C19: =C14+C17+C18 -> -1573990 | D19: =D14+D17+D18 -> -1123270 | E19: =SUM(B19:D19) -> -5668956.7
A20: Résultat net cumulé (après charges à confirmer) | B20: =B19 -> -2971696.7 | C20: =B20+C19 -> -4545686.7 | D20: =C20+D19 -> -5668956.7
A21: Marge nette (résultat net après charges à confirmer ÷ recettes) | B21: =IF(B6=0,0,B19/B6) -> -0.22677483 | C21: =IF(C6=0,0,C19/C6) -> -0.14733761 | D21: =IF(D6=0,0,D19/D6) -> -0.10976294 | E21: =IF(E6=0,0,E19/E6) -> -0.1666328
A23: PASSAGE DU RÉSULTAT À LA CAISSE (modèle, sans charges à confirmer)
A24: Résultat net — modèle | B24: =B14 -> -2276696.7 | C24: =C14 -> -783990 | D24: =D14 -> -333270 | E24: =SUM(B24:D24) -> -3393956.7
A25: + Amortissements (non décaissés) | B25: =-B10 -> 3225000 | C25: =-C10 -> 850000 | D25: =-D10 -> 850000 | E25: =SUM(B25:D25) -> 4925000
A26: + Impôt sur les sociétés (non repris dans la caisse du classeur) | B26: =-B13 -> 0 | C26: =-C13 -> 0 | D26: =-D13 -> 0 | E26: =SUM(B26:D26) -> 0
A27: − Achats de véhicules payés (acompte, mensualités, motos) | B27: =-(Mensuel!B45+Mensuel!C45) -> -3834583.3 | C27: =-Mensuel!D45 -> -90416.667 | D27: =-Mensuel!E45 -> 0 | E27: =SUM(B27:D27) -> -3925000
A28: − Matériel informatique et mobilier acheté (mois 0) | B28: =-(Mensuel!B17+Mensuel!C17) -> -1000000 | C28: =-Mensuel!D17 -> 0 | D28: =-Mensuel!E17 -> 0 | E28: =SUM(B28:D28) -> -1000000
A29: − Bureau de Cotonou : caution et aménagement (mois 0) | B29: =-(Mensuel!B16+Mensuel!C16) -> -500000 | C29: =-Mensuel!D16 -> 0 | D29: =-Mensuel!E16 -> 0 | E29: =SUM(B29:D29) -> -500000
A30: VARIATION DE LA CAISSE (calculée ici) | B30: =SUM(B24:B29) -> -4386280 | C30: =SUM(C24:C29) -> -24406.667 | D30: =SUM(D24:D29) -> 516730 | E30: =SUM(B30:D30) -> -3893956.7
A31: Variation de la caisse (feuille Mensuel) | B31: =Mensuel!B65+Mensuel!C65 -> -4386280 | C31: =Mensuel!D65 -> -24406.667 | D31: =Mensuel!E65 -> 516730 | E31: =SUM(B31:D31) -> -3893956.7
A32: Contrôle : écart (doit être 0) | B32: =ROUND(B30-B31,0) -> 0 | C32: =ROUND(C30-C31,0) -> 0 | D32: =ROUND(D30-D31,0) -> 0 | E32: =SUM(B32:D32) -> 0
A33: Caisse en fin d'année (levée de 15 M comprise) | B33: =Mensuel!C66 -> 10613720 | C33: =Mensuel!D66 -> 10589313 | D33: =Mensuel!E66 -> 11106043
A34: Plus bas niveau de caisse sur 36 mois | B34: =Mensuel!F66 -> 6350174.2
A35: Mois de caisse négative | B35: =Mensuel!F67 -> 0
A37: Lecture : l'avance de 100 000 F par voiture, remboursée au mois 13 (900 000 F), est traitée comme une charge de l'an 2 ; son encaissement initial n'est pas compté en recette (hypothèse du classeur d'origine).

Sheet Mensuel
A1: TamCar — Charges, recettes aux planchers et caisse, mois par mois (FCFA), mois 0 à 36
A2: Les charges sont les blocs du haut ; les recettes (planchers de Mayeul) et la caisse sont en bas. Achats des mois suivants : saisir les quantités en bleu, lignes 7 et 8. Les assurances, trackers et mensualités suivent automatiquement.
A4: Poste | B4: Démarrage (mois 0) | C4: Année 1 (mois 1-12) | D4: Année 2 (mois 13-24) | E4: Année 3 (mois 25-36) | F4: Total 3 ans | G4: 0 | H4: 1 | I4: 2 | J4: 3 | K4: 4 | L4: 5 | M4: 6 | N4: 7 | O4: 8 | P4: 9 | Q4: 10 | R4: 11 | S4: 12 | T4: 13 | U4: 14 | V4: 15 | W4: 16 | X4: 17 | Y4: 18 | Z4: 19 | AA4: 20 | AB4: 21 | AC4: 22 | AD4: 23 | AE4: 24 | AF4: 25 | AG4: 26 | AH4: 27 | AI4: 28 | AJ4: 29 | AK4: 30 | AL4: 31 | AM4: 32 | AN4: 33 | AO4: 34 | AP4: 35 | AQ4: 36
A6: FLOTTE (quantités)
A7: Tricycles achetés ce mois (saisie) | B7: saisie | G7: 0 | H7: =Hypothèses!$B$5 -> 1 | I7: 0 | J7: 0 | K7: 0 | L7: 0 | M7: 0 | N7: 0 | O7: 0 | P7: 0 | Q7: 0 | R7: 0 | S7: 0 | T7: 0 | U7: 0 | V7: 0 | W7: 0 | X7: 0 | Y7: 0 | Z7: 0 | AA7: 0 | AB7: 0 | AC7: 0 | AD7: 0 | AE7: 0 | AF7: 0 | AG7: 0 | AH7: 0 | AI7: 0 | AJ7: 0 | AK7: 0 | AL7: 0 | AM7: 0 | AN7: 0 | AO7: 0 | AP7: 0 | AQ7: 0
A8: Motos achetées ce mois (saisie) | G8: 0 | H8: =Hypothèses!$B$6 -> 5 | I8: 0 | J8: 0 | K8: 0 | L8: 0 | M8: 0 | N8: 0 | O8: 0 | P8: 0 | Q8: 0 | R8: 0 | S8: 0 | T8: 0 | U8: 0 | V8: 0 | W8: 0 | X8: 0 | Y8: 0 | Z8: 0 | AA8: 0 | AB8: 0 | AC8: 0 | AD8: 0 | AE8: 0 | AF8: 0 | AG8: 0 | AH8: 0 | AI8: 0 | AJ8: 0 | AK8: 0 | AL8: 0 | AM8: 0 | AN8: 0 | AO8: 0 | AP8: 0 | AQ8: 0
A9: Tricycles en flotte (cumul) | G9: =G7 -> 0 | H9: =G9+H7 -> 1 | I9: =H9+I7 -> 1 | J9: =I9+J7 -> 1 | K9: =J9+K7 -> 1 | L9: =K9+L7 -> 1 | M9: =L9+M7 -> 1 | N9: =M9+N7 -> 1 | O9: =N9+O7 -> 1 | ... AQ9: =AP9+AQ7 -> 1
A10: Motos en flotte (cumul) | G10: =G8 -> 0 | H10: =G10+H8 -> 5 | I10: =H10+I8 -> 5 | J10: =I10+J8 -> 5 | K10: =J10+K8 -> 5 | L10: =K10+L8 -> 5 | M10: =L10+M8 -> 5 | N10: =M10+N8 -> 5 | O10: =N10+O8 -> 5 | ... AQ10: =AP10+AQ8 -> 5
A12: DÉMARRAGE (mois 0)
A13: Formalisation de la société | B13: =G13 -> 1500000 | C13: =SUM(H13:S13) -> 0 | D13: =SUM(T13:AE13) -> 0 | E13: =SUM(AF13:AQ13) -> 0 | F13: =SUM(B13:E13) -> 1500000 | G13: =Hypothèses!$B$22 -> 1500000 | H13: 0 | I13: 0 | J13: 0 | K13: 0 | L13: 0 | M13: 0 | N13: 0 | O13: 0 | P13: 0 | Q13: 0 | R13: 0 | S13: 0 | T13: 0 | U13: 0 | V13: 0 | W13: 0 | X13: 0 | Y13: 0 | Z13: 0 | AA13: 0 | AB13: 0 | AC13: 0 | AD13: 0 | AE13: 0 | AF13: 0 | AG13: 0 | AH13: 0 | AI13: 0 | AJ13: 0 | AK13: 0 | AL13: 0 | AM13: 0 | AN13: 0 | AO13: 0 | AP13: 0 | AQ13: 0
A14: ANATT (autorisation de transporteur) | B14: =G14 -> 300000 | C14: =SUM(H14:S14) -> 0 | D14: =SUM(T14:AE14) -> 0 | E14: =SUM(AF14:AQ14) -> 0 | F14: =SUM(B14:E14) -> 300000 | G14: =Hypothèses!$B$23 -> 300000 | H14: 0 | I14: 0 | J14: 0 | K14: 0 | L14: 0 | M14: 0 | N14: 0 | O14: 0 | P14: 0 | Q14: 0 | R14: 0 | S14: 0 | T14: 0 | U14: 0 | V14: 0 | W14: 0 | X14: 0 | Y14: 0 | Z14: 0 | AA14: 0 | AB14: 0 | AC14: 0 | AD14: 0 | AE14: 0 | AF14: 0 | AG14: 0 | AH14: 0 | AI14: 0 | AJ14: 0 | AK14: 0 | AL14: 0 | AM14: 0 | AN14: 0 | AO14: 0 | AP14: 0 | AQ14: 0
A15: Juriste (contrats) | B15: =G15 -> 100000 | C15: =SUM(H15:S15) -> 0 | D15: =SUM(T15:AE15) -> 0 | E15: =SUM(AF15:AQ15) -> 0 | F15: =SUM(B15:E15) -> 100000 | G15: =Hypothèses!$B$24 -> 100000 | H15: 0 | I15: 0 | J15: 0 | K15: 0 | L15: 0 | M15: 0 | N15: 0 | O15: 0 | P15: 0 | Q15: 0 | R15: 0 | S15: 0 | T15: 0 | U15: 0 | V15: 0 | W15: 0 | X15: 0 | Y15: 0 | Z15: 0 | AA15: 0 | AB15: 0 | AC15: 0 | AD15: 0 | AE15: 0 | AF15: 0 | AG15: 0 | AH15: 0 | AI15: 0 | AJ15: 0 | AK15: 0 | AL15: 0 | AM15: 0 | AN15: 0 | AO15: 0 | AP15: 0 | AQ15: 0
A16: Bureau de Cotonou (caution, aménagement) | B16: =G16 -> 500000 | C16: =SUM(H16:S16) -> 0 | D16: =SUM(T16:AE16) -> 0 | E16: =SUM(AF16:AQ16) -> 0 | F16: =SUM(B16:E16) -> 500000 | G16: =Hypothèses!$B$25 -> 500000 | H16: 0 | I16: 0 | J16: 0 | K16: 0 | L16: 0 | M16: 0 | N16: 0 | O16: 0 | P16: 0 | Q16: 0 | R16: 0 | S16: 0 | T16: 0 | U16: 0 | V16: 0 | W16: 0 | X16: 0 | Y16: 0 | Z16: 0 | AA16: 0 | AB16: 0 | AC16: 0 | AD16: 0 | AE16: 0 | AF16: 0 | AG16: 0 | AH16: 0 | AI16: 0 | AJ16: 0 | AK16: 0 | AL16: 0 | AM16: 0 | AN16: 0 | AO16: 0 | AP16: 0 | AQ16: 0
A17: Matériel informatique et mobilier (2 bureaux) | B17: =G17 -> 1000000 | C17: =SUM(H17:S17) -> 0 | D17: =SUM(T17:AE17) -> 0 | E17: =SUM(AF17:AQ17) -> 0 | F17: =SUM(B17:E17) -> 1000000 | G17: =Hypothèses!$B$26 -> 1000000 | H17: 0 | I17: 0 | J17: 0 | K17: 0 | L17: 0 | M17: 0 | N17: 0 | O17: 0 | P17: 0 | Q17: 0 | R17: 0 | S17: 0 | T17: 0 | U17: 0 | V17: 0 | W17: 0 | X17: 0 | Y17: 0 | Z17: 0 | AA17: 0 | AB17: 0 | AC17: 0 | AD17: 0 | AE17: 0 | AF17: 0 | AG17: 0 | AH17: 0 | AI17: 0 | AJ17: 0 | AK17: 0 | AL17: 0 | AM17: 0 | AN17: 0 | AO17: 0 | AP17: 0 | AQ17: 0
A18: Marketing de lancement (photo, vidéo, sponsoring) | B18: =G18 -> 1000000 | C18: =SUM(H18:S18) -> 0 | D18: =SUM(T18:AE18) -> 0 | E18: =SUM(AF18:AQ18) -> 0 | F18: =SUM(B18:E18) -> 1000000 | G18: =Hypothèses!$B$27 -> 1000000 | H18: 0 | I18: 0 | J18: 0 | K18: 0 | L18: 0 | M18: 0 | N18: 0 | O18: 0 | P18: 0 | Q18: 0 | R18: 0 | S18: 0 | T18: 0 | U18: 0 | V18: 0 | W18: 0 | X18: 0 | Y18: 0 | Z18: 0 | AA18: 0 | AB18: 0 | AC18: 0 | AD18: 0 | AE18: 0 | AF18: 0 | AG18: 0 | AH18: 0 | AI18: 0 | AJ18: 0 | AK18: 0 | AL18: 0 | AM18: 0 | AN18: 0 | AO18: 0 | AP18: 0 | AQ18: 0
A19: Graphisme | B19: =G19 -> 150000 | C19: =SUM(H19:S19) -> 0 | D19: =SUM(T19:AE19) -> 0 | E19: =SUM(AF19:AQ19) -> 0 | F19: =SUM(B19:E19) -> 150000 | G19: =Hypothèses!$B$28 -> 150000 | H19: 0 | I19: 0 | J19: 0 | K19: 0 | L19: 0 | M19: 0 | N19: 0 | O19: 0 | P19: 0 | Q19: 0 | R19: 0 | S19: 0 | T19: 0 | U19: 0 | V19: 0 | W19: 0 | X19: 0 | Y19: 0 | Z19: 0 | AA19: 0 | AB19: 0 | AC19: 0 | AD19: 0 | AE19: 0 | AF19: 0 | AG19: 0 | AH19: 0 | AI19: 0 | AJ19: 0 | AK19: 0 | AL19: 0 | AM19: 0 | AN19: 0 | AO19: 0 | AP19: 0 | AQ19: 0
A20: Sous-total démarrage | B20: =G20 -> 4550000 | C20: =SUM(H20:S20) -> 0 | D20: =SUM(T20:AE20) -> 0 | E20: =SUM(AF20:AQ20) -> 0 | F20: =SUM(B20:E20) -> 4550000 | G20: =SUM(G13:G19) -> 4550000 | H20: =SUM(H13:H19) -> 0 | I20: =SUM(I13:I19) -> 0 | J20: =SUM(J13:J19) -> 0 | K20: =SUM(K13:K19) -> 0 | L20: =SUM(L13:L19) -> 0 | M20: =SUM(M13:M19) -> 0 | N20: =SUM(N13:N19) -> 0 | ... AQ20: =SUM(AQ13:AQ19) -> 0
A22: FONCTIONNEMENT
A23: Secrétaire | B23: =G23 -> 0 | C23: =SUM(H23:S23) -> 1200000 | D23: =SUM(T23:AE23) -> 1200000 | E23: =SUM(AF23:AQ23) -> 1200000 | F23: =SUM(B23:E23) -> 3600000 | G23: 0 | H23: =Hypothèses!$B$31 -> 100000 | I23: =Hypothèses!$B$31 -> 100000 | J23: =Hypothèses!$B$31 -> 100000 | K23: =Hypothèses!$B$31 -> 100000 | L23: =Hypothèses!$B$31 -> 100000 | M23: =Hypothèses!$B$31 -> 100000 | N23: =Hypothèses!$B$31 -> 100000 | O23: =Hypothèses!$B$31 -> 100000 | ... AQ23: =Hypothèses!$B$31 -> 100000
A24: Infrastructure technique | B24: =G24 -> 0 | C24: =SUM(H24:S24) -> 900000 | D24: =SUM(T24:AE24) -> 900000 | E24: =SUM(AF24:AQ24) -> 900000 | F24: =SUM(B24:E24) -> 2700000 | G24: 0 | H24: =Hypothèses!$B$32 -> 75000 | I24: =Hypothèses!$B$32 -> 75000 | J24: =Hypothèses!$B$32 -> 75000 | K24: =Hypothèses!$B$32 -> 75000 | L24: =Hypothèses!$B$32 -> 75000 | M24: =Hypothèses!$B$32 -> 75000 | N24: =Hypothèses!$B$32 -> 75000 | O24: =Hypothèses!$B$32 -> 75000 | ... AQ24: =Hypothèses!$B$32 -> 75000
A25: Développeur (dès le mois indiqué dans les hypothèses) | B25: =G25 -> 0 | C25: =SUM(H25:S25) -> 0 | D25: =SUM(T25:AE25) -> 2400000 | E25: =SUM(AF25:AQ25) -> 2400000 | F25: =SUM(B25:E25) -> 4800000 | G25: 0 | H25: =IF(H$4>=Hypothèses!$B$34,Hypothèses!$B$33,0) -> 0 | I25: =IF(I$4>=Hypothèses!$B$34,Hypothèses!$B$33,0) -> 0 | J25: =IF(J$4>=Hypothèses!$B$34,Hypothèses!$B$33,0) -> 0 | K25: =IF(K$4>=Hypothèses!$B$34,Hypothèses!$B$33,0) -> 0 | L25: =IF(L$4>=Hypothèses!$B$34,Hypothèses!$B$33,0) -> 0 | M25: =IF(M$4>=Hypothèses!$B$34,Hypothèses!$B$33,0) -> 0 | N25: =IF(N$4>=Hypothèses!$B$34,Hypothèses!$B$33,0) -> 0 | O25: =IF(O$4>=Hypothèses!$B$34,Hypothèses!$B$33,0) -> 0 | ... AQ25: =IF(AQ$4>=Hypothèses!$B$34,Hypothèses!$B$33,0) -> 200000
A26: Outil de développement (Claude Code, mois 1 à 12) | B26: =G26 -> 0 | C26: =SUM(H26:S26) -> 900000 | D26: =SUM(T26:AE26) -> 0 | E26: =SUM(AF26:AQ26) -> 0 | F26: =SUM(B26:E26) -> 900000 | G26: 0 | H26: =IF(H$4<=12,Hypothèses!$B$35,0) -> 75000 | I26: =IF(I$4<=12,Hypothèses!$B$35,0) -> 75000 | J26: =IF(J$4<=12,Hypothèses!$B$35,0) -> 75000 | K26: =IF(K$4<=12,Hypothèses!$B$35,0) -> 75000 | L26: =IF(L$4<=12,Hypothèses!$B$35,0) -> 75000 | M26: =IF(M$4<=12,Hypothèses!$B$35,0) -> 75000 | N26: =IF(N$4<=12,Hypothèses!$B$35,0) -> 75000 | O26: =IF(O$4<=12,Hypothèses!$B$35,0) -> 75000 | ... AQ26: =IF(AQ$4<=12,Hypothèses!$B$35,0) -> 0
A27: Électricité et eau | B27: =G27 -> 0 | C27: =SUM(H27:S27) -> 1200000 | D27: =SUM(T27:AE27) -> 1200000 | E27: =SUM(AF27:AQ27) -> 1200000 | F27: =SUM(B27:E27) -> 3600000 | G27: 0 | H27: =Hypothèses!$B$36 -> 100000 | I27: =Hypothèses!$B$36 -> 100000 | J27: =Hypothèses!$B$36 -> 100000 | K27: =Hypothèses!$B$36 -> 100000 | L27: =Hypothèses!$B$36 -> 100000 | M27: =Hypothèses!$B$36 -> 100000 | N27: =Hypothèses!$B$36 -> 100000 | O27: =Hypothèses!$B$36 -> 100000 | ... AQ27: =Hypothèses!$B$36 -> 100000
A28: Loyer du bureau de Cotonou | B28: =G28 -> 0 | C28: =SUM(H28:S28) -> 600000 | D28: =SUM(T28:AE28) -> 600000 | E28: =SUM(AF28:AQ28) -> 600000 | F28: =SUM(B28:E28) -> 1800000 | G28: 0 | H28: =Hypothèses!$B$37 -> 50000 | I28: =Hypothèses!$B$37 -> 50000 | J28: =Hypothèses!$B$37 -> 50000 | K28: =Hypothèses!$B$37 -> 50000 | L28: =Hypothèses!$B$37 -> 50000 | M28: =Hypothèses!$B$37 -> 50000 | N28: =Hypothèses!$B$37 -> 50000 | O28: =Hypothèses!$B$37 -> 50000 | ... AQ28: =Hypothèses!$B$37 -> 50000
A29: Assurance multirisque professionnelle | B29: =G29 -> 0 | C29: =SUM(H29:S29) -> 600000 | D29: =SUM(T29:AE29) -> 600000 | E29: =SUM(AF29:AQ29) -> 600000 | F29: =SUM(B29:E29) -> 1800000 | G29: 0 | H29: =Hypothèses!$B$38 -> 50000 | I29: =Hypothèses!$B$38 -> 50000 | J29: =Hypothèses!$B$38 -> 50000 | K29: =Hypothèses!$B$38 -> 50000 | L29: =Hypothèses!$B$38 -> 50000 | M29: =Hypothèses!$B$38 -> 50000 | N29: =Hypothèses!$B$38 -> 50000 | O29: =Hypothèses!$B$38 -> 50000 | ... AQ29: =Hypothèses!$B$38 -> 50000
A30: Comptable (par trimestre) | B30: =G30 -> 0 | C30: =SUM(H30:S30) -> 300000 | D30: =SUM(T30:AE30) -> 300000 | E30: =SUM(AF30:AQ30) -> 300000 | F30: =SUM(B30:E30) -> 900000 | G30: 0 | H30: =IF(MOD(H$4,3)=0,Hypothèses!$B$39,0) -> 0 | I30: =IF(MOD(I$4,3)=0,Hypothèses!$B$39,0) -> 0 | J30: =IF(MOD(J$4,3)=0,Hypothèses!$B$39,0) -> 75000 | K30: =IF(MOD(K$4,3)=0,Hypothèses!$B$39,0) -> 0 | L30: =IF(MOD(L$4,3)=0,Hypothèses!$B$39,0) -> 0 | M30: =IF(MOD(M$4,3)=0,Hypothèses!$B$39,0) -> 75000 | N30: =IF(MOD(N$4,3)=0,Hypothèses!$B$39,0) -> 0 | O30: =IF(MOD(O$4,3)=0,Hypothèses!$B$39,0) -> 0 | ... AQ30: =IF(MOD(AQ$4,3)=0,Hypothèses!$B$39,0) -> 75000
A31: Juriste (par trimestre) | B31: =G31 -> 0 | C31: =SUM(H31:S31) -> 200000 | D31: =SUM(T31:AE31) -> 200000 | E31: =SUM(AF31:AQ31) -> 200000 | F31: =SUM(B31:E31) -> 600000 | G31: 0 | H31: =IF(MOD(H$4,3)=0,Hypothèses!$B$40,0) -> 0 | I31: =IF(MOD(I$4,3)=0,Hypothèses!$B$40,0) -> 0 | J31: =IF(MOD(J$4,3)=0,Hypothèses!$B$40,0) -> 50000 | K31: =IF(MOD(K$4,3)=0,Hypothèses!$B$40,0) -> 0 | L31: =IF(MOD(L$4,3)=0,Hypothèses!$B$40,0) -> 0 | M31: =IF(MOD(M$4,3)=0,Hypothèses!$B$40,0) -> 50000 | N31: =IF(MOD(N$4,3)=0,Hypothèses!$B$40,0) -> 0 | O31: =IF(MOD(O$4,3)=0,Hypothèses!$B$40,0) -> 0 | ... AQ31: =IF(MOD(AQ$4,3)=0,Hypothèses!$B$40,0) -> 50000
A32: Promotion de lancement | B32: =G32 -> 0 | C32: =SUM(H32:S32) -> 600000 | D32: =SUM(T32:AE32) -> 0 | E32: =SUM(AF32:AQ32) -> 0 | F32: =SUM(B32:E32) -> 600000 | G32: 0 | H32: =IF(H$4<=Hypothèses!$B$42,Hypothèses!$B$41,0) -> 100000 | I32: =IF(I$4<=Hypothèses!$B$42,Hypothèses!$B$41,0) -> 100000 | J32: =IF(J$4<=Hypothèses!$B$42,Hypothèses!$B$41,0) -> 100000 | K32: =IF(K$4<=Hypothèses!$B$42,Hypothèses!$B$41,0) -> 100000 | L32: =IF(L$4<=Hypothèses!$B$42,Hypothèses!$B$41,0) -> 100000 | M32: =IF(M$4<=Hypothèses!$B$42,Hypothèses!$B$41,0) -> 100000 | N32: =IF(N$4<=Hypothèses!$B$42,Hypothèses!$B$41,0) -> 0 | O32: =IF(O$4<=Hypothèses!$B$42,Hypothèses!$B$41,0) -> 0 | ... AQ32: =IF(AQ$4<=Hypothèses!$B$42,Hypothèses!$B$41,0) -> 0
A33: Responsable des opérations (3 % du volume, plafonné) | B33: =G33 -> 0 | C33: =SUM(H33:S33) -> 1368120 | D33: =SUM(T33:AE33) -> 1368120 | E33: =SUM(AF33:AQ33) -> 1368120 | F33: =SUM(B33:E33) -> 4104360 | G33: 0 | H33: =MIN(Hypothèses!$B$43*(H9*Hypothèses!$B$45+H10*Hypothèses!$B$46+IF(H$4>=Hypothèses!$B$59,Hypothèses!$B$57*Hypothèses!$B$60+Hypothèses!$B$58*Hypothèses!$B$61,0))*Hypothèses!$B$47,Hypothèses!$B$44) -> 114010 | I33: =MIN(Hypothèses!$B$43*(I9*Hypothèses!$B$45+I10*Hypothèses!$B$46+IF(I$4>=Hypothèses!$B$59,Hypothèses!$B$57*Hypothèses!$B$60+Hypothèses!$B$58*Hypothèses!$B$61,0))*Hypothèses!$B$47,Hypothèses!$B$44) -> 114010 | J33: =MIN(Hypothèses!$B$43*(J9*Hypothèses!$B$45+J10*Hypothèses!$B$46+IF(J$4>=Hypothèses!$B$59,Hypothèses!$B$57*Hypothèses!$B$60+Hypothèses!$B$58*Hypothèses!$B$61,0))*Hypothèses!$B$47,Hypothèses!$B$44) -> 114010 | K33: =MIN(Hypothèses!$B$43*(K9*Hypothèses!$B$45+K10*Hypothèses!$B$46+IF(K$4>=Hypothèses!$B$59,Hypothèses!$B$57*Hypothèses!$B$60+Hypothèses!$B$58*Hypothèses!$B$61,0))*Hypothèses!$B$47,Hypothèses!$B$44) -> 114010 | L33: =MIN(Hypothèses!$B$43*(L9*Hypothèses!$B$45+L10*Hypothèses!$B$46+IF(L$4>=Hypothèses!$B$59,Hypothèses!$B$57*Hypothèses!$B$60+Hypothèses!$B$58*Hypothèses!$B$61,0))*Hypothèses!$B$47,Hypothèses!$B$44) -> 114010 | M33: =MIN(Hypothèses!$B$43*(M9*Hypothèses!$B$45+M10*Hypothèses!$B$46+IF(M$4>=Hypothèses!$B$59,Hypothèses!$B$57*Hypothèses!$B$60+Hypothèses!$B$58*Hypothèses!$B$61,0))*Hypothèses!$B$47,Hypothèses!$B$44) -> 114010 | N33: =MIN(Hypothèses!$B$43*(N9*Hypothèses!$B$45+N10*Hypothèses!$B$46+IF(N$4>=Hypothèses!$B$59,Hypothèses!$B$57*Hypothèses!$B$60+Hypothèses!$B$58*Hypothèses!$B$61,0))*Hypothèses!$B$47,Hypothèses!$B$44) -> 114010 | O33: =MIN(Hypothèses!$B$43*(O9*Hypothèses!$B$45+O10*Hypothèses!$B$46+IF(O$4>=Hypothèses!$B$59,Hypothèses!$B$57*Hypothèses!$B$60+Hypothèses!$B$58*Hypothèses!$B$61,0))*Hypothèses!$B$47,Hypothèses!$B$44) -> 114010 | ... AQ33: =MIN(Hypothèses!$B$43*(AQ9*Hypothèses!$B$45+AQ10*Hypothèses!$B$46+IF(AQ$4>=Hypothèses!$B$59,Hypothèses!$B$57*Hypothèses!$B$60+Hypothèses!$B$58*Hypothèses!$B$61,0))*Hypothèses!$B$47,Hypothèses!$B$44) -> 114010
A34: Renouvellement ANATT (mois 13 et 25) | B34: =G34 -> 0 | C34: =SUM(H34:S34) -> 0 | D34: =SUM(T34:AE34) -> 280000 | E34: =SUM(AF34:AQ34) -> 280000 | F34: =SUM(B34:E34) -> 560000 | G34: 0 | H34: =IF(OR(H$4=13,H$4=25),Hypothèses!$B$48,0) -> 0 | I34: =IF(OR(I$4=13,I$4=25),Hypothèses!$B$48,0) -> 0 | J34: =IF(OR(J$4=13,J$4=25),Hypothèses!$B$48,0) -> 0 | K34: =IF(OR(K$4=13,K$4=25),Hypothèses!$B$48,0) -> 0 | L34: =IF(OR(L$4=13,L$4=25),Hypothèses!$B$48,0) -> 0 | M34: =IF(OR(M$4=13,M$4=25),Hypothèses!$B$48,0) -> 0 | N34: =IF(OR(N$4=13,N$4=25),Hypothèses!$B$48,0) -> 0 | O34: =IF(OR(O$4=13,O$4=25),Hypothèses!$B$48,0) -> 0 | ... AQ34: =IF(OR(AQ$4=13,AQ$4=25),Hypothèses!$B$48,0) -> 0
A35: Impôt minimum sur les sociétés (mois 16 et 28) | B35: =G35 -> 0 | C35: =SUM(H35:S35) -> 0 | D35: =SUM(T35:AE35) -> 254000 | E35: =SUM(AF35:AQ35) -> 254000 | F35: =SUM(B35:E35) -> 508000 | G35: 0 | H35: =IF(OR(H$4=16,H$4=28),Hypothèses!$B$49,0) -> 0 | I35: =IF(OR(I$4=16,I$4=28),Hypothèses!$B$49,0) -> 0 | J35: =IF(OR(J$4=16,J$4=28),Hypothèses!$B$49,0) -> 0 | K35: =IF(OR(K$4=16,K$4=28),Hypothèses!$B$49,0) -> 0 | L35: =IF(OR(L$4=16,L$4=28),Hypothèses!$B$49,0) -> 0 | M35: =IF(OR(M$4=16,M$4=28),Hypothèses!$B$49,0) -> 0 | N35: =IF(OR(N$4=16,N$4=28),Hypothèses!$B$49,0) -> 0 | O35: =IF(OR(O$4=16,O$4=28),Hypothèses!$B$49,0) -> 0 | ... AQ35: =IF(OR(AQ$4=16,AQ$4=28),Hypothèses!$B$49,0) -> 0
A36: Patente (mois 13 et 25) | B36: =G36 -> 0 | C36: =SUM(H36:S36) -> 0 | D36: =SUM(T36:AE36) -> 172000 | E36: =SUM(AF36:AQ36) -> 172000 | F36: =SUM(B36:E36) -> 344000 | G36: 0 | H36: =IF(OR(H$4=13,H$4=25),Hypothèses!$B$50+Hypothèses!$B$51*12*Hypothèses!$B$37,0) -> 0 | I36: =IF(OR(I$4=13,I$4=25),Hypothèses!$B$50+Hypothèses!$B$51*12*Hypothèses!$B$37,0) -> 0 | J36: =IF(OR(J$4=13,J$4=25),Hypothèses!$B$50+Hypothèses!$B$51*12*Hypothèses!$B$37,0) -> 0 | K36: =IF(OR(K$4=13,K$4=25),Hypothèses!$B$50+Hypothèses!$B$51*12*Hypothèses!$B$37,0) -> 0 | L36: =IF(OR(L$4=13,L$4=25),Hypothèses!$B$50+Hypothèses!$B$51*12*Hypothèses!$B$37,0) -> 0 | M36: =IF(OR(M$4=13,M$4=25),Hypothèses!$B$50+Hypothèses!$B$51*12*Hypothèses!$B$37,0) -> 0 | N36: =IF(OR(N$4=13,N$4=25),Hypothèses!$B$50+Hypothèses!$B$51*12*Hypothèses!$B$37,0) -> 0 | O36: =IF(OR(O$4=13,O$4=25),Hypothèses!$B$50+Hypothèses!$B$51*12*Hypothèses!$B$37,0) -> 0 | ... AQ36: =IF(OR(AQ$4=13,AQ$4=25),Hypothèses!$B$50+Hypothèses!$B$51*12*Hypothèses!$B$37,0) -> 0
A37: Avance remboursée aux propriétaires des voitures (mois 13) | B37: =G37 -> 0 | C37: =SUM(H37:S37) -> 0 | D37: =SUM(T37:AE37) -> 900000 | E37: =SUM(AF37:AQ37) -> 0 | F37: =SUM(B37:E37) -> 900000 | G37: 0 | H37: =IF(H$4=Hypothèses!$B$59+12,(Hypothèses!$B$57+Hypothèses!$B$58)*Hypothèses!$B$67,0) -> 0 | I37: =IF(I$4=Hypothèses!$B$59+12,(Hypothèses!$B$57+Hypothèses!$B$58)*Hypothèses!$B$67,0) -> 0 | J37: =IF(J$4=Hypothèses!$B$59+12,(Hypothèses!$B$57+Hypothèses!$B$58)*Hypothèses!$B$67,0) -> 0 | K37: =IF(K$4=Hypothèses!$B$59+12,(Hypothèses!$B$57+Hypothèses!$B$58)*Hypothèses!$B$67,0) -> 0 | L37: =IF(L$4=Hypothèses!$B$59+12,(Hypothèses!$B$57+Hypothèses!$B$58)*Hypothèses!$B$67,0) -> 0 | M37: =IF(M$4=Hypothèses!$B$59+12,(Hypothèses!$B$57+Hypothèses!$B$58)*Hypothèses!$B$67,0) -> 0 | N37: =IF(N$4=Hypothèses!$B$59+12,(Hypothèses!$B$57+Hypothèses!$B$58)*Hypothèses!$B$67,0) -> 0 | O37: =IF(O$4=Hypothèses!$B$59+12,(Hypothèses!$B$57+Hypothèses!$B$58)*Hypothèses!$B$67,0) -> 0 | ... AQ37: =IF(AQ$4=Hypothèses!$B$59+12,(Hypothèses!$B$57+Hypothèses!$B$58)*Hypothèses!$B$67,0) -> 0
A38: Épargne NSIA : postes vacants (TamCar paie la cotisation) | B38: =G38 -> 0 | C38: =SUM(H38:S38) -> 78750 | D38: =SUM(T38:AE38) -> 78750 | E38: =SUM(AF38:AQ38) -> 78750 | F38: =SUM(B38:E38) -> 236250 | G38: 0 | H38: =(H9+H10+IF(H$4>=Hypothèses!$B$59,Hypothèses!$B$57+Hypothèses!$B$58,0))*Hypothèses!$B$81/12*Hypothèses!$B$82*Hypothèses!$B$80 -> 6562.5 | I38: =(I9+I10+IF(I$4>=Hypothèses!$B$59,Hypothèses!$B$57+Hypothèses!$B$58,0))*Hypothèses!$B$81/12*Hypothèses!$B$82*Hypothèses!$B$80 -> 6562.5 | J38: =(J9+J10+IF(J$4>=Hypothèses!$B$59,Hypothèses!$B$57+Hypothèses!$B$58,0))*Hypothèses!$B$81/12*Hypothèses!$B$82*Hypothèses!$B$80 -> 6562.5 | K38: =(K9+K10+IF(K$4>=Hypothèses!$B$59,Hypothèses!$B$57+Hypothèses!$B$58,0))*Hypothèses!$B$81/12*Hypothèses!$B$82*Hypothèses!$B$80 -> 6562.5 | L38: =(L9+L10+IF(L$4>=Hypothèses!$B$59,Hypothèses!$B$57+Hypothèses!$B$58,0))*Hypothèses!$B$81/12*Hypothèses!$B$82*Hypothèses!$B$80 -> 6562.5 | M38: =(M9+M10+IF(M$4>=Hypothèses!$B$59,Hypothèses!$B$57+Hypothèses!$B$58,0))*Hypothèses!$B$81/12*Hypothèses!$B$82*Hypothèses!$B$80 -> 6562.5 | N38: =(N9+N10+IF(N$4>=Hypothèses!$B$59,Hypothèses!$B$57+Hypothèses!$B$58,0))*Hypothèses!$B$81/12*Hypothèses!$B$82*Hypothèses!$B$80 -> 6562.5 | O38: =(O9+O10+IF(O$4>=Hypothèses!$B$59,Hypothèses!$B$57+Hypothèses!$B$58,0))*Hypothèses!$B$81/12*Hypothèses!$B$82*Hypothèses!$B$80 -> 6562.5 | ... AQ38: =(AQ9+AQ10+IF(AQ$4>=Hypothèses!$B$59,Hypothèses!$B$57+Hypothèses!$B$58,0))*Hypothèses!$B$81/12*Hypothèses!$B$82*Hypothèses!$B$80 -> 6562.5
A39: Sous-total fonctionnement | B39: =G39 -> 0 | C39: =SUM(H39:S39) -> 7946870 | D39: =SUM(T39:AE39) -> 10452870 | E39: =SUM(AF39:AQ39) -> 9552870 | F39: =SUM(B39:E39) -> 27952610 | G39: =SUM(G23:G38) -> 0 | H39: =SUM(H23:H38) -> 670572.5 | I39: =SUM(I23:I38) -> 670572.5 | J39: =SUM(J23:J38) -> 795572.5 | K39: =SUM(K23:K38) -> 670572.5 | L39: =SUM(L23:L38) -> 670572.5 | M39: =SUM(M23:M38) -> 795572.5 | N39: =SUM(N23:N38) -> 570572.5 | ... AQ39: =SUM(AQ23:AQ38) -> 820572.5
A41: ACHAT DES VÉHICULES
A42: Tricycles : acompte à l'achat | B42: =G42 -> 0 | C42: =SUM(H42:S42) -> 465000 | D42: =SUM(T42:AE42) -> 0 | E42: =SUM(AF42:AQ42) -> 0 | F42: =SUM(B42:E42) -> 465000 | G42: =G7*Hypothèses!$B$9*Hypothèses!$B$10 -> 0 | H42: =H7*Hypothèses!$B$9*Hypothèses!$B$10 -> 465000 | I42: =I7*Hypothèses!$B$9*Hypothèses!$B$10 -> 0 | J42: =J7*Hypothèses!$B$9*Hypothèses!$B$10 -> 0 | K42: =K7*Hypothèses!$B$9*Hypothèses!$B$10 -> 0 | L42: =L7*Hypothèses!$B$9*Hypothèses!$B$10 -> 0 | M42: =M7*Hypothèses!$B$9*Hypothèses!$B$10 -> 0 | N42: =N7*Hypothèses!$B$9*Hypothèses!$B$10 -> 0 | ... AQ42: =AQ7*Hypothèses!$B$9*Hypothèses!$B$10 -> 0
A43: Tricycles : mensualités du solde | B43: =G43 -> 0 | C43: =SUM(H43:S43) -> 994583.33 | D43: =SUM(T43:AE43) -> 90416.667 | E43: =SUM(AF43:AQ43) -> 0 | F43: =SUM(B43:E43) -> 1085000 | G43: =SUMPRODUCT(($G$4:$AQ$4<G$4)*($G$4:$AQ$4>=G$4-Hypothèses!$B$11)*$G$7:$AQ$7)*Hypothèses!$B$9*(1-Hypothèses!$B$10)/Hypothèses!$B$11 -> 0 | H43: =SUMPRODUCT(($G$4:$AQ$4<H$4)*($G$4:$AQ$4>=H$4-Hypothèses!$B$11)*$G$7:$AQ$7)*Hypothèses!$B$9*(1-Hypothèses!$B$10)/Hypothèses!$B$11 -> 0 | I43: =SUMPRODUCT(($G$4:$AQ$4<I$4)*($G$4:$AQ$4>=I$4-Hypothèses!$B$11)*$G$7:$AQ$7)*Hypothèses!$B$9*(1-Hypothèses!$B$10)/Hypothèses!$B$11 -> 90416.667 | J43: =SUMPRODUCT(($G$4:$AQ$4<J$4)*($G$4:$AQ$4>=J$4-Hypothèses!$B$11)*$G$7:$AQ$7)*Hypothèses!$B$9*(1-Hypothèses!$B$10)/Hypothèses!$B$11 -> 90416.667 | K43: =SUMPRODUCT(($G$4:$AQ$4<K$4)*($G$4:$AQ$4>=K$4-Hypothèses!$B$11)*$G$7:$AQ$7)*Hypothèses!$B$9*(1-Hypothèses!$B$10)/Hypothèses!$B$11 -> 90416.667 | L43: =SUMPRODUCT(($G$4:$AQ$4<L$4)*($G$4:$AQ$4>=L$4-Hypothèses!$B$11)*$G$7:$AQ$7)*Hypothèses!$B$9*(1-Hypothèses!$B$10)/Hypothèses!$B$11 -> 90416.667 | M43: =SUMPRODUCT(($G$4:$AQ$4<M$4)*($G$4:$AQ$4>=M$4-Hypothèses!$B$11)*$G$7:$AQ$7)*Hypothèses!$B$9*(1-Hypothèses!$B$10)/Hypothèses!$B$11 -> 90416.667 | N43: =SUMPRODUCT(($G$4:$AQ$4<N$4)*($G$4:$AQ$4>=N$4-Hypothèses!$B$11)*$G$7:$AQ$7)*Hypothèses!$B$9*(1-Hypothèses!$B$10)/Hypothèses!$B$11 -> 90416.667 | ... AQ43: =SUMPRODUCT(($G$4:$AQ$4<AQ$4)*($G$4:$AQ$4>=AQ$4-Hypothèses!$B$11)*$G$7:$AQ$7)*Hypothèses!$B$9*(1-Hypothèses!$B$10)/Hypothèses!$B$11 -> 0
A44: Motos : achat comptant | B44: =G44 -> 0 | C44: =SUM(H44:S44) -> 2375000 | D44: =SUM(T44:AE44) -> 0 | E44: =SUM(AF44:AQ44) -> 0 | F44: =SUM(B44:E44) -> 2375000 | G44: =G8*Hypothèses!$B$12 -> 0 | H44: =H8*Hypothèses!$B$12 -> 2375000 | I44: =I8*Hypothèses!$B$12 -> 0 | J44: =J8*Hypothèses!$B$12 -> 0 | K44: =K8*Hypothèses!$B$12 -> 0 | L44: =L8*Hypothèses!$B$12 -> 0 | M44: =M8*Hypothèses!$B$12 -> 0 | N44: =N8*Hypothèses!$B$12 -> 0 | ... AQ44: =AQ8*Hypothèses!$B$12 -> 0
A45: Sous-total achat des véhicules | B45: =G45 -> 0 | C45: =SUM(H45:S45) -> 3834583.3 | D45: =SUM(T45:AE45) -> 90416.667 | E45: =SUM(AF45:AQ45) -> 0 | F45: =SUM(B45:E45) -> 3925000 | G45: =SUM(G42:G44) -> 0 | H45: =SUM(H42:H44) -> 2840000 | I45: =SUM(I42:I44) -> 90416.667 | J45: =SUM(J42:J44) -> 90416.667 | K45: =SUM(K42:K44) -> 90416.667 | L45: =SUM(L42:L44) -> 90416.667 | M45: =SUM(M42:M44) -> 90416.667 | N45: =SUM(N42:N44) -> 90416.667 | ... AQ45: =SUM(AQ42:AQ44) -> 0
...

Sheet Synthèse
A1: TamCar — Charges, recettes aux planchers et caisse (FCFA)
A2: Flotte TamCar : 1 tricycle thermique (30 % + 12 mois) + 5 motos électriques (comptant), plus 9 voitures mises à disposition (6 Essentiel + 3 Confort, VIP non compté). Recettes = planchers de Mayeul. Pour changer quoi que ce soit : feuille Hypothèses (cellules bleues).
A4: Poste | B4: Démarrage (mois 0) | C4: Année 1 | D4: Année 2 | E4: Année 3 | F4: Total 3 ans
A5: 1. Démarrage
A6: Formalisation de la société | B6: =Mensuel!B13 -> 1500000 | C6: =Mensuel!C13 -> 0 | D6: =Mensuel!D13 -> 0 | E6: =Mensuel!E13 -> 0 | F6: =Mensuel!F13 -> 1500000
A7: ANATT (autorisation de transporteur) | B7: =Mensuel!B14 -> 300000 | C7: =Mensuel!C14 -> 0 | D7: =Mensuel!D14 -> 0 | E7: =Mensuel!E14 -> 0 | F7: =Mensuel!F14 -> 300000
